Workbook

Sheet Main Page
B2: Top 5 Drivers + Top 5 Constructors Snapshot Tables
B3: Rank | C3: Driver | D3: Points | E3: Rank | F3: Team | G3: Points
B4: 1 | C4: ='Drivers'' Standings'!AE2 -> ANT | D4: ='Drivers'' Standings'!AF2 -> 219 | E4: 1 | F4: ='Constructors Standings'!AC2 -> Mercedes | G4: ='Constructors Standings'!AD2 -> 379
B5: 2 | C5: ='Drivers'' Standings'!AE3 -> HAM | D5: ='Drivers'' Standings'!AF3 -> 169 | E5: 2 | F5: ='Constructors Standings'!AC3 -> Ferrari | G5: ='Constructors Standings'!AD3 -> 307
B6: 3 | C6: ='Drivers'' Standings'!AE4 -> RUS | D6: ='Drivers'' Standings'!AF4 -> 160 | E6: 3 | F6: ='Constructors Standings'!AC4 -> McLaren | G6: ='Constructors Standings'!AD4 -> 220
B7: 4 | C7: ='Drivers'' Standings'!AE5 -> LEC | D7: ='Drivers'' Standings'!AF5 -> 138 | E7: 4 | F7: ='Constructors Standings'!AC5 -> Red Bull Racing | G7: ='Constructors Standings'!AD5 -> 177
B8: 5 | C8: ='Drivers'' Standings'!AE6 -> NOR | D8: ='Drivers'' Standings'!AF6 -> 128 | E8: 5 | F8: ='Constructors Standings'!AC6 -> Racing Bulls | G8: ='Constructors Standings'!AD6 -> 66

Sheet Drivers' Standings
C1: AUSTRALIA | D1: CHINA | E1: JAPAN | F1: BAHRAIN | G1: SAUDI ARABIA | H1: MIAMI | I1: CANADA | J1: MONACO | K1: BARCELONA | L1: AUSTRIA | M1: GREAT BRITAIN | N1: BELGIUM | O1: HUNGARY | P1: NETHERLANDS | Q1: ITALY | R1: SPAIN (MADRID) | S1: AZERBAIJAN | T1: SINGAPORE | U1: UNITED STATES | V1: MEXICO | W1: BRAZIL | X1: LAS VEGAS | Y1: QATAR | Z1: ABU DHABI | AA1: POS | AB1: POINTS | AD1: RANK | AE1: DRIVER | AF1: POINTS | AH1: F1 Champion
A2: Kimi Antonelli | B2: ANT | C2: =IFERROR(VLOOKUP(MATCH($B2,INDEX('Race Resuts'!$A$2:$W$23,0,MATCH(C$1,'Race Resuts'!$A$1:$W$1,0)),0),'Points Refrence'!$A$2:$B$11,2,FALSE),0) -> 18 | D2: =IFERROR(_xlfn.XLOOKUP(MATCH($B2,INDEX('Race Resuts'!$B$2:$W$23,0,MATCH(D$1,'Race Resuts'!$B$1:$W$1,0)),0),'Points Refrence'!$A$2:$A$11,'Points Refrence'!$B$2:$B$11,0),0)+IFERROR(_xlfn.XLOOKUP(MATCH($B2,INDEX('Sprint Race Results'!$B$2:$G$23,0,MATCH(D$1,'Sprint Race Results'!$B$1:$G$1,0)),0),'Points Refrence'!$D$2:$D$9,'Points Refrence'!$E$2:$E$9,0),0) -> 29 | E2: =IFERROR(VLOOKUP(MATCH($B2,INDEX('Race Resuts'!$A$2:$W$23,0,MATCH(E$1,'Race Resuts'!$A$1:$W$1,0)),0),'Points Refrence'!$A$2:$B$11,2,FALSE),0) -> 25 | F2: =IFERROR(VLOOKUP(MATCH($B2,INDEX('Race Resuts'!$A$2:$W$23,0,MATCH(F$1,'Race Resuts'!$A$1:$W$1,0)),0),'Points Refrence'!$A$2:$B$11,2,FALSE),0) -> 0 | G2: =IFERROR(VLOOKUP(MATCH($B2,INDEX('Race Resuts'!$A$2:$W$23,0,MATCH(G$1,'Race Resuts'!$A$1:$W$1,0)),0),'Points Refrence'!$A$2:$B$11,2,FALSE),0) -> 0 | H2: =IFERROR(VLOOKUP(MATCH($B2,INDEX('Race Resuts'!$B$2:$W$23,0,MATCH(H$1,'Race Resuts'!$B$1:$W$1,0)),0),'Points Refrence'!$A$2:$B$11,2,FALSE),0)+IFERROR(VLOOKUP(MATCH($B2,INDEX('Sprint Race Results'!$B$2:$G$23,0,MATCH(H$1,'Sprint Race Results'!$B$1:$G$1,0)),0),'Points Refrence'!$D$2:$E$9,2,FALSE),0) -> 28 | I2: =IFERROR(VLOOKUP(MATCH($B2,INDEX('Race Resuts'!$B$2:$W$23,0,MATCH(I$1,'Race Resuts'!$B$1:$W$1,0)),0),'Points Refrence'!$A$2:$B$11,2,FALSE),0)+IFERROR(VLOOKUP(MATCH($B2,INDEX('Sprint Race Results'!$B$2:$G$23,0,MATCH(I$1,'Sprint Race Results'!$B$1:$G$1,0)),0),'Points Refrence'!$D$2:$E$9,2,FALSE),0) -> 31 | J2: =IFERROR(VLOOKUP(MATCH($B2,INDEX('Race Resuts'!$A$2:$W$23,0,MATCH(J$1,'Race Resuts'!$A$1:$W$1,0)),0),'Points Refrence'!$A$2:$B$11,2,FALSE),0) -> 25 | K2: =IFERROR(VLOOKUP(MATCH($B2,INDEX('Race Resuts'!$A$2:$W$23,0,MATCH(K$1,'Race Resuts'!$A$1:$W$1,0)),0),'Points Refrence'!$A$2:$B$11,2,FALSE),0) -> 0 | L2: =IFERROR(VLOOKUP(MATCH($B2,INDEX('Race Resuts'!$A$2:$W$23,0,MATCH(L$1,'Race Resuts'!$A$1:$W$1,0)),0),'Points Refrence'!$A$2:$B$11,2,FALSE),0) -> 15 | M2: =IFERROR(VLOOKUP(MATCH($B2,INDEX('Race Resuts'!$B$2:$W$23,0,MATCH(M$1,'Race Resuts'!$B$1:$W$1,0)),0),'Points Refrence'!$A$2:$B$11,2,FALSE),0)+IFERROR(VLOOKUP(MATCH($B2,INDEX('Sprint Race Results'!$B$2:$G$23,0,MATCH(M$1,'Sprint Race Results'!$B$1:$G$1,0)),0),'Points Refrence'!$D$2:$E$9,2,FALSE),0) -> 8 | N2: =IFERROR(VLOOKUP(MATCH($B2,INDEX('Race Resuts'!$A$2:$W$23,0,MATCH(N$1,'Race Resuts'!$A$1:$W$1,0)),0),'Points Refrence'!$A$2:$B$11,2,FALSE),0) -> 25 | O2: =IFERROR(VLOOKUP(MATCH($B2,INDEX('Race Resuts'!$A$2:$W$23,0,MATCH(O$1,'Race Resuts'!$A$1:$W$1,0)),0),'Points Refrence'!$A$2:$B$11,2,FALSE),0) -> 15 | P2: =IFERROR(VLOOKUP(MATCH($B2,INDEX('Race Resuts'!$B$2:$W$23,0,MATCH(P$1,'Race Resuts'!$B$1:$W$1,0)),0),'Points Refrence'!$A$2:$B$11,2,FALSE),0)+IFERROR(VLOOKUP(MATCH($B2,INDEX('Sprint Race Results'!$B$2:$G$23,0,MATCH(P$1,'Sprint Race Results'!$B$1:$G$1,0)),0),'Points Refrence'!$D$2:$E$9,2,FALSE),0) -> 0 | Q2: =IFERROR(VLOOKUP(MATCH($B2,INDEX('Race Resuts'!$A$2:$W$23,0,MATCH(Q$1,'Race Resuts'!$A$1:$W$1,0)),0),'Points Refrence'!$A$2:$B$11,2,FALSE),0) -> 0 | R2: =IFERROR(VLOOKUP(MATCH($B2,INDEX('Race Resuts'!$A$2:$W$23,0,MATCH(R$1,'Race Resuts'!$A$1:$W$1,0)),0),'Points Refrence'!$A$2:$B$11,2,FALSE),0) -> 0 | S2: =IFERROR(VLOOKUP(MATCH($B2,INDEX('Race Resuts'!$A$2:$W$23,0,MATCH(S$1,'Race Resuts'!$A$1:$W$1,0)),0),'Points Refrence'!$A$2:$B$11,2,FALSE),0) -> 0 | T2: =IFERROR(VLOOKUP(MATCH($B2,INDEX('Race Resuts'!$B$2:$W$23,0,MATCH(T$1,'Race Resuts'!$B$1:$W$1,0)),0),'Points Refrence'!$A$2:$B$11,2,FALSE),0)+IFERROR(VLOOKUP(MATCH($B2,INDEX('Sprint Race Results'!$B$2:$G$23,0,MATCH(T$1,'Sprint Race Results'!$B$1:$G$1,0)),0),'Points Refrence'!$D$2:$E$9,2,FALSE),0) -> 0 | U2: =IFERROR(VLOOKUP(MATCH($B2,INDEX('Race Resuts'!$A$2:$W$23,0,MATCH(U$1,'Race Resuts'!$A$1:$W$1,0)),0),'Points Refrence'!$A$2:$B$11,2,FALSE),0) -> 0 | V2: =IFERROR(VLOOKUP(MATCH($B2,INDEX('Race Resuts'!$A$2:$W$23,0,MATCH(V$1,'Race Resuts'!$A$1:$W$1,0)),0),'Points Refrence'!$A$2:$B$11,2,FALSE),0) -> 0 | W2: =IFERROR(VLOOKUP(MATCH($B2,INDEX('Race Resuts'!$A$2:$W$23,0,MATCH(W$1,'Race Resuts'!$A$1:$W$1,0)),0),'Points Refrence'!$A$2:$B$11,2,FALSE),0) -> 0 | X2: =IFERROR(VLOOKUP(MATCH($B2,INDEX('Race Resuts'!$A$2:$W$23,0,MATCH(X$1,'Race Resuts'!$A$1:$W$1,0)),0),'Points Refrence'!$A$2:$B$11,2,FALSE),0) -> 0 | Y2: =IFERROR(VLOOKUP(MATCH($B2,INDEX('Race Resuts'!$A$2:$W$23,0,MATCH(Y$1,'Race Resuts'!$A$1:$W$1,0)),0),'Points Refrence'!$A$2:$B$11,2,FALSE),0) -> 0 | Z2: =IFERROR(VLOOKUP(MATCH($B2,INDEX('Race Resuts'!$A$2:$W$23,0,MATCH(Z$1,'Race Resuts'!$A$1:$W$1,0)),0),'Points Refrence'!$A$2:$B$11,2,FALSE),0) -> 0 | AA2: =RANK(AB2,$AB$2:$AB$23,0)+COUNTIF($AB$2:AB2,AB2)-1 -> 1 | AB2: =SUM(C2:Z2) -> 219 | AD2: =ROW()-1 -> 1 | AE2: =INDEX($B$2:$B$23,MATCH(AD2,$AA$2:$AA$23,0)) -> ANT | AF2: =INDEX($AB$2:$AB$23,MATCH(AD2,$AA$2:$AA$23,0)) -> 219 | AH2: =AE$2 -> ANT
A3: George Russell | B3: RUS | C3: =IFERROR(VLOOKUP(MATCH($B3,INDEX('Race Resuts'!$A$2:$W$23,0,MATCH(C$1,'Race Resuts'!$A$1:$W$1,0)),0),'Points Refrence'!$A$2:$B$11,2,FALSE),0) -> 25 | D3: =IFERROR(_xlfn.XLOOKUP(MATCH($B3,INDEX('Race Resuts'!$B$2:$W$23,0,MATCH(D$1,'Race Resuts'!$B$1:$W$1,0)),0),'Points Refrence'!$A$2:$A$11,'Points Refrence'!$B$2:$B$11,0),0)+IFERROR(_xlfn.XLOOKUP(MATCH($B3,INDEX('Sprint Race Results'!$B$2:$G$23,0,MATCH(D$1,'Sprint Race Results'!$B$1:$G$1,0)),0),'Points Refrence'!$D$2:$D$9,'Points Refrence'!$E$2:$E$9,0),0) -> 26 | E3: =IFERROR(VLOOKUP(MATCH($B3,INDEX('Race Resuts'!$A$2:$W$23,0,MATCH(E$1,'Race Resuts'!$A$1:$W$1,0)),0),'Points Refrence'!$A$2:$B$11,2,FALSE),0) -> 12 | F3: =IFERROR(VLOOKUP(MATCH($B3,INDEX('Race Resuts'!$A$2:$W$23,0,MATCH(F$1,'Race Resuts'!$A$1:$W$1,0)),0),'Points Refrence'!$A$2:$B$11,2,FALSE),0) -> 0 | G3: =IFERROR(VLOOKUP(MATCH($B3,INDEX('Race Resuts'!$A$2:$W$23,0,MATCH(G$1,'Race Resuts'!$A$1:$W$1,0)),0),'Points Refrence'!$A$2:$B$11,2,FALSE),0) -> 0 | H3: =IFERROR(VLOOKUP(MATCH($B3,INDEX('Race Resuts'!$B$2:$W$23,0,MATCH(H$1,'Race Resuts'!$B$1:$W$1,0)),0),'Points Refrence'!$A$2:$B$11,2,FALSE),0)+IFERROR(VLOOKUP(MATCH($B3,INDEX('Sprint Race Results'!$B$2:$G$23,0,MATCH(H$1,'Sprint Race Results'!$B$1:$G$1,0)),0),'Points Refrence'!$D$2:$E$9,2,FALSE),0) -> 17 | I3: =IFERROR(VLOOKUP(MATCH($B3,INDEX('Race Resuts'!$B$2:$W$23,0,MATCH(I$1,'Race Resuts'!$B$1:$W$1,0)),0),'Points Refrence'!$A$2:$B$11,2,FALSE),0)+IFERROR(VLOOKUP(MATCH($B3,INDEX('Sprint Race Results'!$B$2:$G$23,0,MATCH(I$1,'Sprint Race Results'!$B$1:$G$1,0)),0),'Points Refrence'!$D$2:$E$9,2,FALSE),0) -> 8 | J3: =IFERROR(VLOOKUP(MATCH($B3,INDEX('Race Resuts'!$A$2:$W$23,0,MATCH(J$1,'Race Resuts'!$A$1:$W$1,0)),0),'Points Refrence'!$A$2:$B$11,2,FALSE),0) -> 0 | K3: =IFERROR(VLOOKUP(MATCH($B3,INDEX('Race Resuts'!$A$2:$W$23,0,MATCH(K$1,'Race Resuts'!$A$1:$W$1,0)),0),'Points Refrence'!$A$2:$B$11,2,FALSE),0) -> 18 | L3: =IFERROR(VLOOKUP(MATCH($B3,INDEX('Race Resuts'!$A$2:$W$23,0,MATCH(L$1,'Race Resuts'!$A$1:$W$1,0)),0),'Points Refrence'!$A$2:$B$11,2,FALSE),0) -> 25 | M3: =IFERROR(VLOOKUP(MATCH($B3,INDEX('Race Resuts'!$B$2:$W$23,0,MATCH(M$1,'Race Resuts'!$B$1:$W$1,0)),0),'Points Refrence'!$A$2:$B$11,2,FALSE),0)+IFERROR(VLOOKUP(MATCH($B3,INDEX('Sprint Race Results'!$B$2:$G$23,0,MATCH(M$1,'Sprint Race Results'!$B$1:$G$1,0)),0),'Points Refrence'!$D$2:$E$9,2,FALSE),0) -> 23 | N3: =IFERROR(VLOOKUP(MATCH($B3,INDEX('Race Resuts'!$A$2:$W$23,0,MATCH(N$1,'Race Resuts'!$A$1:$W$1,0)),0),'Points Refrence'!$A$2:$B$11,2,FALSE),0) -> 0 | O3: =IFERROR(VLOOKUP(MATCH($B3,INDEX('Race Resuts'!$A$2:$W$23,0,MATCH(O$1,'Race Resuts'!$A$1:$W$1,0)),0),'Points Refrence'!$A$2:$B$11,2,FALSE),0) -> 6 | P3: =IFERROR(VLOOKUP(MATCH($B3,INDEX('Race Resuts'!$B$2:$W$23,0,MATCH(P$1,'Race Resuts'!$B$1:$W$1,0)),0),'Points Refrence'!$A$2:$B$11,2,FALSE),0)+IFERROR(VLOOKUP(MATCH($B3,INDEX('Sprint Race Results'!$B$2:$G$23,0,MATCH(P$1,'Sprint Race Results'!$B$1:$G$1,0)),0),'Points Refrence'!$D$2:$E$9,2,FALSE),0) -> 0 | Q3: =IFERROR(VLOOKUP(MATCH($B3,INDEX('Race Resuts'!$A$2:$W$23,0,MATCH(Q$1,'Race Resuts'!$A$1:$W$1,0)),0),'Points Refrence'!$A$2:$B$11,2,FALSE),0) -> 0 | R3: =IFERROR(VLOOKUP(MATCH($B3,INDEX('Race Resuts'!$A$2:$W$23,0,MATCH(R$1,'Race Resuts'!$A$1:$W$1,0)),0),'Points Refrence'!$A$2:$B$11,2,FALSE),0) -> 0 | S3: =IFERROR(VLOOKUP(MATCH($B3,INDEX('Race Resuts'!$A$2:$W$23,0,MATCH(S$1,'Race Resuts'!$A$1:$W$1,0)),0),'Points Refrence'!$A$2:$B$11,2,FALSE),0) -> 0 | T3: =IFERROR(VLOOKUP(MATCH($B3,INDEX('Race Resuts'!$B$2:$W$23,0,MATCH(T$1,'Race Resuts'!$B$1:$W$1,0)),0),'Points Refrence'!$A$2:$B$11,2,FALSE),0)+IFERROR(VLOOKUP(MATCH($B3,INDEX('Sprint Race Results'!$B$2:$G$23,0,MATCH(T$1,'Sprint Race Results'!$B$1:$G$1,0)),0),'Points Refrence'!$D$2:$E$9,2,FALSE),0) -> 0 | U3: =IFERROR(VLOOKUP(MATCH($B3,INDEX('Race Resuts'!$A$2:$W$23,0,MATCH(U$1,'Race Resuts'!$A$1:$W$1,0)),0),'Points Refrence'!$A$2:$B$11,2,FALSE),0) -> 0 | V3: =IFERROR(VLOOKUP(MATCH($B3,INDEX('Race Resuts'!$A$2:$W$23,0,MATCH(V$1,'Race Resuts'!$A$1:$W$1,0)),0),'Points Refrence'!$A$2:$B$11,2,FALSE),0) -> 0 | W3: =IFERROR(VLOOKUP(MATCH($B3,INDEX('Race Resuts'!$A$2:$W$23,0,MATCH(W$1,'Race Resuts'!$A$1:$W$1,0)),0),'Points Refrence'!$A$2:$B$11,2,FALSE),0) -> 0 | X3: =IFERROR(VLOOKUP(MATCH($B3,INDEX('Race Resuts'!$A$2:$W$23,0,MATCH(X$1,'Race Resuts'!$A$1:$W$1,0)),0),'Points Refrence'!$A$2:$B$11,2,FALSE),0) -> 0 | Y3: =IFERROR(VLOOKUP(MATCH($B3,INDEX('Race Resuts'!$A$2:$W$23,0,MATCH(Y$1,'Race Resuts'!$A$1:$W$1,0)),0),'Points Refrence'!$A$2:$B$11,2,FALSE),0) -> 0 | Z3: =IFERROR(VLOOKUP(MATCH($B3,INDEX('Race Resuts'!$A$2:$W$23,0,MATCH(Z$1,'Race Resuts'!$A$1:$W$1,0)),0),'Points Refrence'!$A$2:$B$11,2,FALSE),0) -> 0 | AA3: =RANK(AB3,$AB$2:$AB$23,0)+COUNTIF($AB$2:AB3,AB3)-1 -> 3 | AB3: =SUM(C3:Z3) -> 160 | AD3: =ROW()-1 -> 2 | AE3: =INDEX($B$2:$B$23,MATCH(AD3,$AA$2:$AA$23,0)) -> HAM | AF3: =INDEX($AB$2:$AB$23,MATCH(AD3,$AA$2:$AA$23,0)) -> 169
A4: Lewis Hamilton | B4: HAM | C4: =IFERROR(VLOOKUP(MATCH($B4,INDEX('Race Resuts'!$A$2:$W$23,0,MATCH(C$1,'Race Resuts'!$A$1:$W$1,0)),0),'Points Refrence'!$A$2:$B$11,2,FALSE),0) -> 12 | D4: =IFERROR(_xlfn.XLOOKUP(MATCH($B4,INDEX('Race Resuts'!$B$2:$W$23,0,MATCH(D$1,'Race Resuts'!$B$1:$W$1,0)),0),'Points Refrence'!$A$2:$A$11,'Points Refrence'!$B$2:$B$11,0),0)+IFERROR(_xlfn.XLOOKUP(MATCH($B4,INDEX('Sprint Race Results'!$B$2:$G$23,0,MATCH(D$1,'Sprint Race Results'!$B$1:$G$1,0)),0),'Points Refrence'!$D$2:$D$9,'Points Refrence'!$E$2:$E$9,0),0) -> 21 | E4: =IFERROR(VLOOKUP(MATCH($B4,INDEX('Race Resuts'!$A$2:$W$23,0,MATCH(E$1,'Race Resuts'!$A$1:$W$1,0)),0),'Points Refrence'!$A$2:$B$11,2,FALSE),0) -> 8 | F4: =IFERROR(VLOOKUP(MATCH($B4,INDEX('Race Resuts'!$A$2:$W$23,0,MATCH(F$1,'Race Resuts'!$A$1:$W$1,0)),0),'Points Refrence'!$A$2:$B$11,2,FALSE),0) -> 0 | G4: =IFERROR(VLOOKUP(MATCH($B4,INDEX('Race Resuts'!$A$2:$W$23,0,MATCH(G$1,'Race Resuts'!$A$1:$W$1,0)),0),'Points Refrence'!$A$2:$B$11,2,FALSE),0) -> 0 | H4: =IFERROR(VLOOKUP(MATCH($B4,INDEX('Race Resuts'!$B$2:$W$23,0,MATCH(H$1,'Race Resuts'!$B$1:$W$1,0)),0),'Points Refrence'!$A$2:$B$11,2,FALSE),0)+IFERROR(VLOOKUP(MATCH($B4,INDEX('Sprint Race Results'!$B$2:$G$23,0,MATCH(H$1,'Sprint Race Results'!$B$1:$G$1,0)),0),'Points Refrence'!$D$2:$E$9,2,FALSE),0) -> 10 | I4: =IFERROR(VLOOKUP(MATCH($B4,INDEX('Race Resuts'!$B$2:$W$23,0,MATCH(I$1,'Race Resuts'!$B$1:$W$1,0)),0),'Points Refrence'!$A$2:$B$11,2,FALSE),0)+IFERROR(VLOOKUP(MATCH($B4,INDEX('Sprint Race Results'!$B$2:$G$23,0,MATCH(I$1,'Sprint Race Results'!$B$1:$G$1,0)),0),'Points Refrence'!$D$2:$E$9,2,FALSE),0) -> 21 | J4: =IFERROR(VLOOKUP(MATCH($B4,INDEX('Race Resuts'!$A$2:$W$23,0,MATCH(J$1,'Race Resuts'!$A$1:$W$1,0)),0),'Points Refrence'!$A$2:$B$11,2,FALSE),0) -> 18 | K4: =IFERROR(VLOOKUP(MATCH($B4,INDEX('Race Resuts'!$A$2:$W$23,0,MATCH(K$1,'Race Resuts'!$A$1:$W$1,0)),0),'Points Refrence'!$A$2:$B$11,2,FALSE),0) -> 25 | L4: =IFERROR(VLOOKUP(MATCH($B4,INDEX('Race Resuts'!$A$2:$W$23,0,MATCH(L$1,'Race Resuts'!$A$1:$W$1,0)),0),'Points Refrence'!$A$2:$B$11,2,FALSE),0) -> 10 | M4: =IFERROR(VLOOKUP(MATCH($B4,INDEX('Race Resuts'!$B$2:$W$23,0,MATCH(M$1,'Race Resuts'!$B$1:$W$1,0)),0),'Points Refrence'!$A$2:$B$11,2,FALSE),0)+IFERROR(VLOOKUP(MATCH($B4,INDEX('Sprint Race Results'!$B$2:$G$23,0,MATCH(M$1,'Sprint Race Results'!$B$1:$G$1,0)),0),'Points Refrence'!$D$2:$E$9,2,FALSE),0) -> 22 | N4: =IFERROR(VLOOKUP(MATCH($B4,INDEX('Race Resuts'!$A$2:$W$23,0,MATCH(N$1,'Race Resuts'!$A$1:$W$1,0)),0),'Points Refrence'!$A$2:$B$11,2,FALSE),0) -> 12 | O4: =IFERROR(VLOOKUP(MATCH($B4,INDEX('Race Resuts'!$A$2:$W$23,0,MATCH(O$1,'Race Resuts'!$A$1:$W$1,0)),0),'Points Refrence'!$A$2:$B$11,2,FALSE),0) -> 10 | P4: =IFERROR(VLOOKUP(MATCH($B4,INDEX('Race Resuts'!$B$2:$W$23,0,MATCH(P$1,'Race Resuts'!$B$1:$W$1,0)),0),'Points Refrence'!$A$2:$B$11,2,FALSE),0)+IFERROR(VLOOKUP(MATCH($B4,INDEX('Sprint Race Results'!$B$2:$G$23,0,MATCH(P$1,'Sprint Race Results'!$B$1:$G$1,0)),0),'Points Refrence'!$D$2:$E$9,2,FALSE),0) -> 0 | Q4: =IFERROR(VLOOKUP(MATCH($B4,INDEX('Race Resuts'!$A$2:$W$23,0,MATCH(Q$1,'Race Resuts'!$A$1:$W$1,0)),0),'Points Refrence'!$A$2:$B$11,2,FALSE),0) -> 0 | R4: =IFERROR(VLOOKUP(MATCH($B4,INDEX('Race Resuts'!$A$2:$W$23,0,MATCH(R$1,'Race Resuts'!$A$1:$W$1,0)),0),'Points Refrence'!$A$2:$B$11,2,FALSE),0) -> 0 | S4: =IFERROR(VLOOKUP(MATCH($B4,INDEX('Race Resuts'!$A$2:$W$23,0,MATCH(S$1,'Race Resuts'!$A$1:$W$1,0)),0),'Points Refrence'!$A$2:$B$11,2,FALSE),0) -> 0 | T4: =IFERROR(VLOOKUP(MATCH($B4,INDEX('Race Resuts'!$B$2:$W$23,0,MATCH(T$1,'Race Resuts'!$B$1:$W$1,0)),0),'Points Refrence'!$A$2:$B$11,2,FALSE),0)+IFERROR(VLOOKUP(MATCH($B4,INDEX('Sprint Race Results'!$B$2:$G$23,0,MATCH(T$1,'Sprint Race Results'!$B$1:$G$1,0)),0),'Points Refrence'!$D$2:$E$9,2,FALSE),0) -> 0 | U4: =IFERROR(VLOOKUP(MATCH($B4,INDEX('Race Resuts'!$A$2:$W$23,0,MATCH(U$1,'Race Resuts'!$A$1:$W$1,0)),0),'Points Refrence'!$A$2:$B$11,2,FALSE),0) -> 0 | V4: =IFERROR(VLOOKUP(MATCH($B4,INDEX('Race Resuts'!$A$2:$W$23,0,MATCH(V$1,'Race Resuts'!$A$1:$W$1,0)),0),'Points Refrence'!$A$2:$B$11,2,FALSE),0) -> 0 | W4: =IFERROR(VLOOKUP(MATCH($B4,INDEX('Race Resuts'!$A$2:$W$23,0,MATCH(W$1,'Race Resuts'!$A$1:$W$1,0)),0),'Points Refrence'!$A$2:$B$11,2,FALSE),0) -> 0 | X4: =IFERROR(VLOOKUP(MATCH($B4,INDEX('Race Resuts'!$A$2:$W$23,0,MATCH(X$1,'Race Resuts'!$A$1:$W$1,0)),0),'Points Refrence'!$A$2:$B$11,2,FALSE),0) -> 0 | Y4: =IFERROR(VLOOKUP(MATCH($B4,INDEX('Race Resuts'!$A$2:$W$23,0,MATCH(Y$1,'Race Resuts'!$A$1:$W$1,0)),0),'Points Refrence'!$A$2:$B$11,2,FALSE),0) -> 0 | Z4: =IFERROR(VLOOKUP(MATCH($B4,INDEX('Race Resuts'!$A$2:$W$23,0,MATCH(Z$1,'Race Resuts'!$A$1:$W$1,0)),0),'Points Refrence'!$A$2:$B$11,2,FALSE),0) -> 0 | AA4: =RANK(AB4,$AB$2:$AB$23,0)+COUNTIF($AB$2:AB4,AB4)-1 -> 2 | AB4: =SUM(C4:Z4) -> 169 | AD4: =ROW()-1 -> 3 | AE4: =INDEX($B$2:$B$23,MATCH(AD4,$AA$2:$AA$23,0)) -> RUS | AF4: =INDEX($AB$2:$AB$23,MATCH(AD4,$AA$2:$AA$23,0)) -> 160
A5: Charles Leclerc | B5: LEC | C5: =IFERROR(VLOOKUP(MATCH($B5,INDEX('Race Resuts'!$A$2:$W$23,0,MATCH(C$1,'Race Resuts'!$A$1:$W$1,0)),0),'Points Refrence'!$A$2:$B$11,2,FALSE),0) -> 15 | D5: =IFERROR(_xlfn.XLOOKUP(MATCH($B5,INDEX('Race Resuts'!$B$2:$W$23,0,MATCH(D$1,'Race Resuts'!$B$1:$W$1,0)),0),'Points Refrence'!$A$2:$A$11,'Points Refrence'!$B$2:$B$11,0),0)+IFERROR(_xlfn.XLOOKUP(MATCH($B5,INDEX('Sprint Race Results'!$B$2:$G$23,0,MATCH(D$1,'Sprint Race Results'!$B$1:$G$1,0)),0),'Points Refrence'!$D$2:$D$9,'Points Refrence'!$E$2:$E$9,0),0) -> 19 | E5: =IFERROR(VLOOKUP(MATCH($B5,INDEX('Race Resuts'!$A$2:$W$23,0,MATCH(E$1,'Race Resuts'!$A$1:$W$1,0)),0),'Points Refrence'!$A$2:$B$11,2,FALSE),0) -> 15 | F5: =IFERROR(VLOOKUP(MATCH($B5,INDEX('Race Resuts'!$A$2:$W$23,0,MATCH(F$1,'Race Resuts'!$A$1:$W$1,0)),0),'Points Refrence'!$A$2:$B$11,2,FALSE),0) -> 0 | G5: =IFERROR(VLOOKUP(MATCH($B5,INDEX('Race Resuts'!$A$2:$W$23,0,MATCH(G$1,'Race Resuts'!$A$1:$W$1,0)),0),'Points Refrence'!$A$2:$B$11,2,FALSE),0) -> 0 | H5: =IFERROR(VLOOKUP(MATCH($B5,INDEX('Race Resuts'!$B$2:$W$23,0,MATCH(H$1,'Race Resuts'!$B$1:$W$1,0)),0),'Points Refrence'!$A$2:$B$11,2,FALSE),0)+IFERROR(VLOOKUP(MATCH($B5,INDEX('Sprint Race Results'!$B$2:$G$23,0,MATCH(H$1,'Sprint Race Results'!$B$1:$G$1,0)),0),'Points Refrence'!$D$2:$E$9,2,FALSE),0) -> 10 | I5: =IFERROR(VLOOKUP(MATCH($B5,INDEX('Race Resuts'!$B$2:$W$23,0,MATCH(I$1,'Race Resuts'!$B$1:$W$1,0)),0),'Points Refrence'!$A$2:$B$11,2,FALSE),0)+IFERROR(VLOOKUP(MATCH($B5,INDEX('Sprint Race Results'!$B$2:$G$23,0,MATCH(I$1,'Sprint Race Results'!$B$1:$G$1,0)),0),'Points Refrence'!$D$2:$E$9,2,FALSE),0) -> 16 | J5: =IFERROR(VLOOKUP(MATCH($B5,INDEX('Race Resuts'!$A$2:$W$23,0,MATCH(J$1,'Race Resuts'!$A$1:$W$1,0)),0),'Points Refrence'!$A$2:$B$11,2,FALSE),0) -> 0 | K5: =IFERROR(VLOOKUP(MATCH($B5,INDEX('Race Resuts'!$A$2:$W$23,0,MATCH(K$1,'Race Resuts'!$A$1:$W$1,0)),0),'Points Refrence'!$A$2:$B$11,2,FALSE),0) -> 0 | L5: =IFERROR(VLOOKUP(MATCH($B5,INDEX('Race Resuts'!$A$2:$W$23,0,MATCH(L$1,'Race Resuts'!$A$1:$W$1,0)),0),'Points Refrence'!$A$2:$B$11,2,FALSE),0) -> 4 | M5: =IFERROR(VLOOKUP(MATCH($B5,INDEX('Race Resuts'!$B$2:$W$23,0,MATCH(M$1,'Race Resuts'!$B$1:$W$1,0)),0),'Points Refrence'!$A$2:$B$11,2,FALSE),0)+IFERROR(VLOOKUP(MATCH($B5,INDEX('Sprint Race Results'!$B$2:$G$23,0,MATCH(M$1,'Sprint Race Results'!$B$1:$G$1,0)),0),'Points Refrence'!$D$2:$E$9,2,FALSE),0) -> 29 | N5: =IFERROR(VLOOKUP(MATCH($B5,INDEX('Race Resuts'!$A$2:$W$23,0,MATCH(N$1,'Race Resuts'!$A$1:$W$1,0)),0),'Points Refrence'!$A$2:$B$11,2,FALSE),0) -> 18 | O5: =IFERROR(VLOOKUP(MATCH($B5,INDEX('Race Resuts'!$A$2:$W$23,0,MATCH(O$1,'Race Resuts'!$A$1:$W$1,0)),0),'Points Refrence'!$A$2:$B$11,2,FALSE),0) -> 12 | P5: =IFERROR(VLOOKUP(MATCH($B5,INDEX('Race Resuts'!$B$2:$W$23,0,MATCH(P$1,'Race Resuts'!$B$1:$W$1,0)),0),'Points Refrence'!$A$2:$B$11,2,FALSE),0)+IFERROR(VLOOKUP(MATCH($B5,INDEX('Sprint Race Results'!$B$2:$G$23,0,MATCH(P$1,'Sprint Race Results'!$B$1:$G$1,0)),0),'Points Refrence'!$D$2:$E$9,2,FALSE),0) -> 0 | Q5: =IFERROR(VLOOKUP(MATCH($B5,INDEX('Race Resuts'!$A$2:$W$23,0,MATCH(Q$1,'Race Resuts'!$A$1:$W$1,0)),0),'Points Refrence'!$A$2:$B$11,2,FALSE),0) -> 0 | R5: =IFERROR(VLOOKUP(MATCH($B5,INDEX('Race Resuts'!$A$2:$W$23,0,MATCH(R$1,'Race Resuts'!$A$1:$W$1,0)),0),'Points Refrence'!$A$2:$B$11,2,FALSE),0) -> 0 | S5: =IFERROR(VLOOKUP(MATCH($B5,INDEX('Race Resuts'!$A$2:$W$23,0,MATCH(S$1,'Race Resuts'!$A$1:$W$1,0)),0),'Points Refrence'!$A$2:$B$11,2,FALSE),0) -> 0 | T5: =IFERROR(VLOOKUP(MATCH($B5,INDEX('Race Resuts'!$B$2:$W$23,0,MATCH(T$1,'Race Resuts'!$B$1:$W$1,0)),0),'Points Refrence'!$A$2:$B$11,2,FALSE),0)+IFERROR(VLOOKUP(MATCH($B5,INDEX('Sprint Race Results'!$B$2:$G$23,0,MATCH(T$1,'Sprint Race Results'!$B$1:$G$1,0)),0),'Points Refrence'!$D$2:$E$9,2,FALSE),0) -> 0 | U5: =IFERROR(VLOOKUP(MATCH($B5,INDEX('Race Resuts'!$A$2:$W$23,0,MATCH(U$1,'Race Resuts'!$A$1:$W$1,0)),0),'Points Refrence'!$A$2:$B$11,2,FALSE),0) -> 0 | V5: =IFERROR(VLOOKUP(MATCH($B5,INDEX('Race Resuts'!$A$2:$W$23,0,MATCH(V$1,'Race Resuts'!$A$1:$W$1,0)),0),'Points Refrence'!$A$2:$B$11,2,FALSE),0) -> 0 | W5: =IFERROR(VLOOKUP(MATCH($B5,INDEX('Race Resuts'!$A$2:$W$23,0,MATCH(W$1,'Race Resuts'!$A$1:$W$1,0)),0),'Points Refrence'!$A$2:$B$11,2,FALSE),0) -> 0 | X5: =IFERROR(VLOOKUP(MATCH($B5,INDEX('Race Resuts'!$A$2:$W$23,0,MATCH(X$1,'Race Resuts'!$A$1:$W$1,0)),0),'Points Refrence'!$A$2:$B$11,2,FALSE),0) -> 0 | Y5: =IFERROR(VLOOKUP(MATCH($B5,INDEX('Race Resuts'!$A$2:$W$23,0,MATCH(Y$1,'Race Resuts'!$A$1:$W$1,0)),0),'Points Refrence'!$A$2:$B$11,2,FALSE),0) -> 0 | Z5: =IFERROR(VLOOKUP(MATCH($B5,INDEX('Race Resuts'!$A$2:$W$23,0,MATCH(Z$1,'Race Resuts'!$A$1:$W$1,0)),0),'Points Refrence'!$A$2:$B$11,2,FALSE),0) -> 0 | AA5: =RANK(AB5,$AB$2:$AB$23,0)+COUNTIF($AB$2:AB5,AB5)-1 -> 4 | AB5: =SUM(C5:Z5) -> 138 | AD5: =ROW()-1 -> 4 | AE5: =INDEX($B$2:$B$23,MATCH(AD5,$AA$2:$AA$23,0)) -> LEC | AF5: =INDEX($AB$2:$AB$23,MATCH(AD5,$AA$2:$AA$23,0)) -> 138
A6: Lando Norris | B6: NOR | C6: =IFERROR(VLOOKUP(MATCH($B6,INDEX('Race Resuts'!$A$2:$W$23,0,MATCH(C$1,'Race Resuts'!$A$1:$W$1,0)),0),'Points Refrence'!$A$2:$B$11,2,FALSE),0) -> 10 | D6: =IFERROR(_xlfn.XLOOKUP(MATCH($B6,INDEX('Race Resuts'!$B$2:$W$23,0,MATCH(D$1,'Race Resuts'!$B$1:$W$1,0)),0),'Points Refrence'!$A$2:$A$11,'Points Refrence'!$B$2:$B$11,0),0)+IFERROR(_xlfn.XLOOKUP(MATCH($B6,INDEX('Sprint Race Results'!$B$2:$G$23,0,MATCH(D$1,'Sprint Race Results'!$B$1:$G$1,0)),0),'Points Refrence'!$D$2:$D$9,'Points Refrence'!$E$2:$E$9,0),0) -> 5 | E6: =IFERROR(VLOOKUP(MATCH($B6,INDEX('Race Resuts'!$A$2:$W$23,0,MATCH(E$1,'Race Resuts'!$A$1:$W$1,0)),0),'Points Refrence'!$A$2:$B$11,2,FALSE),0) -> 10 | F6: =IFERROR(VLOOKUP(MATCH($B6,INDEX('Race Resuts'!$A$2:$W$23,0,MATCH(F$1,'Race Resuts'!$A$1:$W$1,0)),0),'Points Refrence'!$A$2:$B$11,2,FALSE),0) -> 0 | G6: =IFERROR(VLOOKUP(MATCH($B6,INDEX('Race Resuts'!$A$2:$W$23,0,MATCH(G$1,'Race Resuts'!$A$1:$W$1,0)),0),'Points Refrence'!$A$2:$B$11,2,FALSE),0) -> 0 | H6: =IFERROR(VLOOKUP(MATCH($B6,INDEX('Race Resuts'!$B$2:$W$23,0,MATCH(H$1,'Race Resuts'!$B$1:$W$1,0)),0),'Points Refrence'!$A$2:$B$11,2,FALSE),0)+IFERROR(VLOOKUP(MATCH($B6,INDEX('Sprint Race Results'!$B$2:$G$23,0,MATCH(H$1,'Sprint Race Results'!$B$1:$G$1,0)),0),'Points Refrence'!$D$2:$E$9,2,FALSE),0) -> 26 | I6: =IFERROR(VLOOKUP(MATCH($B6,INDEX('Race Resuts'!$B$2:$W$23,0,MATCH(I$1,'Race Resuts'!$B$1:$W$1,0)),0),'Points Refrence'!$A$2:$B$11,2,FALSE),0)+IFERROR(VLOOKUP(MATCH($B6,INDEX('Sprint Race Results'!$B$2:$G$23,0,MATCH(I$1,'Sprint Race Results'!$B$1:$G$1,0)),0),'Points Refrence'!$D$2:$E$9,2,FALSE),0) -> 7 | J6: =IFERROR(VLOOKUP(MATCH($B6,INDEX('Race Resuts'!$A$2:$W$23,0,MATCH(J$1,'Race Resuts'!$A$1:$W$1,0)),0),'Points Refrence'!$A$2:$B$11,2,FALSE),0) -> 0 | K6: =IFERROR(VLOOKUP(MATCH($B6,INDEX('Race Resuts'!$A$2:$W$23,0,MATCH(K$1,'Race Resuts'!$A$1:$W$1,0)),0),'Points Refrence'!$A$2:$B$11,2,FALSE),0) -> 15 | L6: =IFERROR(VLOOKUP(MATCH($B6,INDEX('Race Resuts'!$A$2:$W$23,0,MATCH(L$1,'Race Resuts'!$A$1:$W$1,0)),0),'Points Refrence'!$A$2:$B$11,2,FALSE),0) -> 6 | M6: =IFERROR(VLOOKUP(MATCH($B6,INDEX('Race Resuts'!$B$2:$W$23,0,MATCH(M$1,'Race Resuts'!$B$1:$W$1,0)),0),'Points Refrence'!$A$2:$B$11,2,FALSE),0)+IFERROR(VLOOKUP(MATCH($B6,INDEX('Sprint Race Results'!$B$2:$G$23,0,MATCH(M$1,'Sprint Race Results'!$B$1:$G$1,0)),0),'Points Refrence'!$D$2:$E$9,2,FALSE),0) -> 18 | N6: =IFERROR(VLOOKUP(MATCH($B6,INDEX('Race Resuts'!$A$2:$W$23,0,MATCH(N$1,'Race Resuts'!$A$1:$W$1,0)),0),'Points Refrence'!$A$2:$B$11,2,FALSE),0) -> 6 | O6: =IFERROR(VLOOKUP(MATCH($B6,INDEX('Race Resuts'!$A$2:$W$23,0,MATCH(O$1,'Race Resuts'!$A$1:$W$1,0)),0),'Points Refrence'!$A$2:$B$11,2,FALSE),0) -> 25 | P6: =IFERROR(VLOOKUP(MATCH($B6,INDEX('Race Resuts'!$B$2:$W$23,0,MATCH(P$1,'Race Resuts'!$B$1:$W$1,0)),0),'Points Refrence'!$A$2:$B$11,2,FALSE),0)+IFERROR(VLOOKUP(MATCH($B6,INDEX('Sprint Race Results'!$B$2:$G$23,0,MATCH(P$1,'Sprint Race Results'!$B$1:$G$1,0)),0),'Points Refrence'!$D$2:$E$9,2,FALSE),0) -> 0 | Q6: =IFERROR(VLOOKUP(MATCH($B6,INDEX('Race Resuts'!$A$2:$W$23,0,MATCH(Q$1,'Race Resuts'!$A$1:$W$1,0)),0),'Points Refrence'!$A$2:$B$11,2,FALSE),0) -> 0 | R6: =IFERROR(VLOOKUP(MATCH($B6,INDEX('Race Resuts'!$A$2:$W$23,0,MATCH(R$1,'Race Resuts'!$A$1:$W$1,0)),0),'Points Refrence'!$A$2:$B$11,2,FALSE),0) -> 0 | S6: =IFERROR(VLOOKUP(MATCH($B6,INDEX('Race Resuts'!$A$2:$W$23,0,MATCH(S$1,'Race Resuts'!$A$1:$W$1,0)),0),'Points Refrence'!$A$2:$B$11,2,FALSE),0) -> 0 | T6: =IFERROR(VLOOKUP(MATCH($B6,INDEX('Race Resuts'!$B$2:$W$23,0,MATCH(T$1,'Race Resuts'!$B$1:$W$1,0)),0),'Points Refrence'!$A$2:$B$11,2,FALSE),0)+IFERROR(VLOOKUP(MATCH($B6,INDEX('Sprint Race Results'!$B$2:$G$23,0,MATCH(T$1,'Sprint Race Results'!$B$1:$G$1,0)),0),'Points Refrence'!$D$2:$E$9,2,FALSE),0) -> 0 | U6: =IFERROR(VLOOKUP(MATCH($B6,INDEX('Race Resuts'!$A$2:$W$23,0,MATCH(U$1,'Race Resuts'!$A$1:$W$1,0)),0),'Points Refrence'!$A$2:$B$11,2,FALSE),0) -> 0 | V6: =IFERROR(VLOOKUP(MATCH($B6,INDEX('Race Resuts'!$A$2:$W$23,0,MATCH(V$1,'Race Resuts'!$A$1:$W$1,0)),0),'Points Refrence'!$A$2:$B$11,2,FALSE),0) -> 0 | W6: =IFERROR(VLOOKUP(MATCH($B6,INDEX('Race Resuts'!$A$2:$W$23,0,MATCH(W$1,'Race Resuts'!$A$1:$W$1,0)),0),'Points Refrence'!$A$2:$B$11,2,FALSE),0) -> 0 | X6: =IFERROR(VLOOKUP(MATCH($B6,INDEX('Race Resuts'!$A$2:$W$23,0,MATCH(X$1,'Race Resuts'!$A$1:$W$1,0)),0),'Points Refrence'!$A$2:$B$11,2,FALSE),0) -> 0 | Y6: =IFERROR(VLOOKUP(MATCH($B6,INDEX('Race Resuts'!$A$2:$W$23,0,MATCH(Y$1,'Race Resuts'!$A$1:$W$1,0)),0),'Points Refrence'!$A$2:$B$11,2,FALSE),0) -> 0 | Z6: =IFERROR(VLOOKUP(MATCH($B6,INDEX('Race Resuts'!$A$2:$W$23,0,MATCH(Z$1,'Race Resuts'!$A$1:$W$1,0)),0),'Points Refrence'!$A$2:$B$11,2,FALSE),0) -> 0 | AA6: =RANK(AB6,$AB$2:$AB$23,0)+COUNTIF($AB$2:AB6,AB6)-1 -> 5 | AB6: =SUM(C6:Z6) -> 128 | AD6: =ROW()-1 -> 5 | AE6: =INDEX($B$2:$B$23,MATCH(AD6,$AA$2:$AA$23,0)) -> NOR | AF6: =INDEX($AB$2:$AB$23,MATCH(AD6,$AA$2:$AA$23,0)) -> 128
A7: Oscar Piastri | B7: PIA | C7: =IFERROR(VLOOKUP(MATCH($B7,INDEX('Race Resuts'!$A$2:$W$23,0,MATCH(C$1,'Race Resuts'!$A$1:$W$1,0)),0),'Points Refrence'!$A$2:$B$11,2,FALSE),0) -> 0 | D7: =IFERROR(_xlfn.XLOOKUP(MATCH($B7,INDEX('Race Resuts'!$B$2:$W$23,0,MATCH(D$1,'Race Resuts'!$B$1:$W$1,0)),0),'Points Refrence'!$A$2:$A$11,'Points Refrence'!$B$2:$B$11,0),0)+IFERROR(_xlfn.XLOOKUP(MATCH($B7,INDEX('Sprint Race Results'!$B$2:$G$23,0,MATCH(D$1,'Sprint Race Results'!$B$1:$G$1,0)),0),'Points Refrence'!$D$2:$D$9,'Points Refrence'!$E$2:$E$9,0),0) -> 3 | E7: =IFERROR(VLOOKUP(MATCH($B7,INDEX('Race Resuts'!$A$2:$W$23,0,MATCH(E$1,'Race Resuts'!$A$1:$W$1,0)),0),'Points Refrence'!$A$2:$B$11,2,FALSE),0) -> 18 | F7: =IFERROR(VLOOKUP(MATCH($B7,INDEX('Race Resuts'!$A$2:$W$23,0,MATCH(F$1,'Race Resuts'!$A$1:$W$1,0)),0),'Points Refrence'!$A$2:$B$11,2,FALSE),0) -> 0 | G7: =IFERROR(VLOOKUP(MATCH($B7,INDEX('Race Resuts'!$A$2:$W$23,0,MATCH(G$1,'Race Resuts'!$A$1:$W$1,0)),0),'Points Refrence'!$A$2:$B$11,2,FALSE),0) -> 0 | H7: =IFERROR(VLOOKUP(MATCH($B7,INDEX('Race Resuts'!$B$2:$W$23,0,MATCH(H$1,'Race Resuts'!$B$1:$W$1,0)),0),'Points Refrence'!$A$2:$B$11,2,FALSE),0)+IFERROR(VLOOKUP(MATCH($B7,INDEX('Sprint Race Results'!$B$2:$G$23,0,MATCH(H$1,'Sprint Race Results'!$B$1:$G$1,0)),0),'Points Refrence'!$D$2:$E$9,2,FALSE),0) -> 22 | I7: =IFERROR(VLOOKUP(MATCH($B7,INDEX('Race Resuts'!$B$2:$W$23,0,MATCH(I$1,'Race Resuts'!$B$1:$W$1,0)),0),'Points Refrence'!$A$2:$B$11,2,FALSE),0)+IFERROR(VLOOKUP(MATCH($B7,INDEX('Sprint Race Results'!$B$2:$G$23,0,MATCH(I$1,'Sprint Race Results'!$B$1:$G$1,0)),0),'Points Refrence'!$D$2:$E$9,2,FALSE),0) -> 5 | J7: =IFERROR(VLOOKUP(MATCH($B7,INDEX('Race Resuts'!$A$2:$W$23,0,MATCH(J$1,'Race Resuts'!$A$1:$W$1,0)),0),'Points Refrence'!$A$2:$B$11,2,FALSE),0) -> 10 | K7: =IFERROR(VLOOKUP(MATCH($B7,INDEX('Race Resuts'!$A$2:$W$23,0,MATCH(K$1,'Race Resuts'!$A$1:$W$1,0)),0),'Points Refrence'!$A$2:$B$11,2,FALSE),0) -> 10 | L7: =IFERROR(VLOOKUP(MATCH($B7,INDEX('Race Resuts'!$A$2:$W$23,0,MATCH(L$1,'Race Resuts'!$A$1:$W$1,0)),0),'Points Refrence'!$A$2:$B$11,2,FALSE),0) -> 12 | M7: =IFERROR(VLOOKUP(MATCH($B7,INDEX('Race Resuts'!$B$2:$W$23,0,MATCH(M$1,'Race Resuts'!$B$1:$W$1,0)),0),'Points Refrence'!$A$2:$B$11,2,FALSE),0)+IFERROR(VLOOKUP(MATCH($B7,INDEX('Sprint Race Results'!$B$2:$G$23,0,MATCH(M$1,'Sprint Race Results'!$B$1:$G$1,0)),0),'Points Refrence'!$D$2:$E$9,2,FALSE),0) -> 2 | N7: =IFERROR(VLOOKUP(MATCH($B7,INDEX('Race Resuts'!$A$2:$W$23,0,MATCH(N$1,'Race Resuts'!$A$1:$W$1,0)),0),'Points Refrence'!$A$2:$B$11,2,FALSE),0) -> 10 | O7: =IFERROR(VLOOKUP(MATCH($B7,INDEX('Race Resuts'!$A$2:$W$23,0,MATCH(O$1,'Race Resuts'!$A$1:$W$1,0)),0),'Points Refrence'!$A$2:$B$11,2,FALSE),0) -> 0 | P7: =IFERROR(VLOOKUP(MATCH($B7,INDEX('Race Resuts'!$B$2:$W$23,0,MATCH(P$1,'Race Resuts'!$B$1:$W$1,0)),0),'Points Refrence'!$A$2:$B$11,2,FALSE),0)+IFERROR(VLOOKUP(MATCH($B7,INDEX('Sprint Race Results'!$B$2:$G$23,0,MATCH(P$1,'Sprint Race Results'!$B$1:$G$1,0)),0),'Points Refrence'!$D$2:$E$9,2,FALSE),0) -> 0 | Q7: =IFERROR(VLOOKUP(MATCH($B7,INDEX('Race Resuts'!$A$2:$W$23,0,MATCH(Q$1,'Race Resuts'!$A$1:$W$1,0)),0),'Points Refrence'!$A$2:$B$11,2,FALSE),0) -> 0 | R7: =IFERROR(VLOOKUP(MATCH($B7,INDEX('Race Resuts'!$A$2:$W$23,0,MATCH(R$1,'Race Resuts'!$A$1:$W$1,0)),0),'Points Refrence'!$A$2:$B$11,2,FALSE),0) -> 0 | S7: =IFERROR(VLOOKUP(MATCH($B7,INDEX('Race Resuts'!$A$2:$W$23,0,MATCH(S$1,'Race Resuts'!$A$1:$W$1,0)),0),'Points Refrence'!$A$2:$B$11,2,FALSE),0) -> 0 | T7: =IFERROR(VLOOKUP(MATCH($B7,INDEX('Race Resuts'!$B$2:$W$23,0,MATCH(T$1,'Race Resuts'!$B$1:$W$1,0)),0),'Points Refrence'!$A$2:$B$11,2,FALSE),0)+IFERROR(VLOOKUP(MATCH($B7,INDEX('Sprint Race Results'!$B$2:$G$23,0,MATCH(T$1,'Sprint Race Results'!$B$1:$G$1,0)),0),'Points Refrence'!$D$2:$E$9,2,FALSE),0) -> 0 | U7: =IFERROR(VLOOKUP(MATCH($B7,INDEX('Race Resuts'!$A$2:$W$23,0,MATCH(U$1,'Race Resuts'!$A$1:$W$1,0)),0),'Points Refrence'!$A$2:$B$11,2,FALSE),0) -> 0 | V7: =IFERROR(VLOOKUP(MATCH($B7,INDEX('Race Resuts'!$A$2:$W$23,0,MATCH(V$1,'Race Resuts'!$A$1:$W$1,0)),0),'Points Refrence'!$A$2:$B$11,2,FALSE),0) -> 0 | W7: =IFERROR(VLOOKUP(MATCH($B7,INDEX('Race Resuts'!$A$2:$W$23,0,MATCH(W$1,'Race Resuts'!$A$1:$W$1,0)),0),'Points Refrence'!$A$2:$B$11,2,FALSE),0) -> 0 | X7: =IFERROR(VLOOKUP(MATCH($B7,INDEX('Race Resuts'!$A$2:$W$23,0,MATCH(X$1,'Race Resuts'!$A$1:$W$1,0)),0),'Points Refrence'!$A$2:$B$11,2,FALSE),0) -> 0 | Y7: =IFERROR(VLOOKUP(MATCH($B7,INDEX('Race Resuts'!$A$2:$W$23,0,MATCH(Y$1,'Race Resuts'!$A$1:$W$1,0)),0),'Points Refrence'!$A$2:$B$11,2,FALSE),0) -> 0 | Z7: =IFERROR(VLOOKUP(MATCH($B7,INDEX('Race Resuts'!$A$2:$W$23,0,MATCH(Z$1,'Race Resuts'!$A$1:$W$1,0)),0),'Points Refrence'!$A$2:$B$11,2,FALSE),0) -> 0 | AA7: =RANK(AB7,$AB$2:$AB$23,0)+COUNTIF($AB$2:AB7,AB7)-1 -> 7 | AB7: =SUM(C7:Z7) -> 92 | AD7: =ROW()-1 -> 6 | AE7: =INDEX($B$2:$B$23,MATCH(AD7,$AA$2:$AA$23,0)) -> VER | AF7: =INDEX($AB$2:$AB$23,MATCH(AD7,$AA$2:$AA$23,0)) -> 109
A8: Max Verstappen | B8: VER | C8: =IFERROR(VLOOKUP(MATCH($B8,INDEX('Race Resuts'!$A$2:$W$23,0,MATCH(C$1,'Race Resuts'!$A$1:$W$1,0)),0),'Points Refrence'!$A$2:$B$11,2,FALSE),0) -> 8 | D8: =IFERROR(_xlfn.XLOOKUP(MATCH($B8,INDEX('Race Resuts'!$B$2:$W$23,0,MATCH(D$1,'Race Resuts'!$B$1:$W$1,0)),0),'Points Refrence'!$A$2:$A$11,'Points Refrence'!$B$2:$B$11,0),0)+IFERROR(_xlfn.XLOOKUP(MATCH($B8,INDEX('Sprint Race Results'!$B$2:$G$23,0,MATCH(D$1,'Sprint Race Results'!$B$1:$G$1,0)),0),'Points Refrence'!$D$2:$D$9,'Points Refrence'!$E$2:$E$9,0),0) -> 0 | E8: =IFERROR(VLOOKUP(MATCH($B8,INDEX('Race Resuts'!$A$2:$W$23,0,MATCH(E$1,'Race Resuts'!$A$1:$W$1,0)),0),'Points Refrence'!$A$2:$B$11,2,FALSE),0) -> 4 | F8: =IFERROR(VLOOKUP(MATCH($B8,INDEX('Race Resuts'!$A$2:$W$23,0,MATCH(F$1,'Race Resuts'!$A$1:$W$1,0)),0),'Points Refrence'!$A$2:$B$11,2,FALSE),0) -> 0 | G8: =IFERROR(VLOOKUP(MATCH($B8,INDEX('Race Resuts'!$A$2:$W$23,0,MATCH(G$1,'Race Resuts'!$A$1:$W$1,0)),0),'Points Refrence'!$A$2:$B$11,2,FALSE),0) -> 0 | H8: =IFERROR(VLOOKUP(MATCH($B8,INDEX('Race Resuts'!$B$2:$W$23,0,MATCH(H$1,'Race Resuts'!$B$1:$W$1,0)),0),'Points Refrence'!$A$2:$B$11,2,FALSE),0)+IFERROR(VLOOKUP(MATCH($B8,INDEX('Sprint Race Results'!$B$2:$G$23,0,MATCH(H$1,'Sprint Race Results'!$B$1:$G$1,0)),0),'Points Refrence'!$D$2:$E$9,2,FALSE),0) -> 14 | I8: =IFERROR(VLOOKUP(MATCH($B8,INDEX('Race Resuts'!$B$2:$W$23,0,MATCH(I$1,'Race Resuts'!$B$1:$W$1,0)),0),'Points Refrence'!$A$2:$B$11,2,FALSE),0)+IFERROR(VLOOKUP(MATCH($B8,INDEX('Sprint Race Results'!$B$2:$G$23,0,MATCH(I$1,'Sprint Race Results'!$B$1:$G$1,0)),0),'Points Refrence'!$D$2:$E$9,2,FALSE),0) -> 17 | J8: =IFERROR(VLOOKUP(MATCH($B8,INDEX('Race Resuts'!$A$2:$W$23,0,MATCH(J$1,'Race Resuts'!$A$1:$W$1,0)),0),'Points Refrence'!$A$2:$B$11,2,FALSE),0) -> 0 | K8: =IFERROR(VLOOKUP(MATCH($B8,INDEX('Race Resuts'!$A$2:$W$23,0,MATCH(K$1,'Race Resuts'!$A$1:$W$1,0)),0),'Points Refrence'!$A$2:$B$11,2,FALSE),0) -> 12 | L8: =IFERROR(VLOOKUP(MATCH($B8,INDEX('Race Resuts'!$A$2:$W$23,0,MATCH(L$1,'Race Resuts'!$A$1:$W$1,0)),0),'Points Refrence'!$A$2:$B$11,2,FALSE),0) -> 18 | M8: =IFERROR(VLOOKUP(MATCH($B8,INDEX('Race Resuts'!$B$2:$W$23,0,MATCH(M$1,'Race Resuts'!$B$1:$W$1,0)),0),'Points Refrence'!$A$2:$B$11,2,FALSE),0)+IFERROR(VLOOKUP(MATCH($B8,INDEX('Sprint Race Results'!$B$2:$G$23,0,MATCH(M$1,'Sprint Race Results'!$B$1:$G$1,0)),0),'Points Refrence'!$D$2:$E$9,2,FALSE),0) -> 3 | N8: =IFERROR(VLOOKUP(MATCH($B8,INDEX('Race Resuts'!$A$2:$W$23,0,MATCH(N$1,'Race Resuts'!$A$1:$W$1,0)),0),'Points Refrence'!$A$2:$B$11,2,FALSE),0) -> 15 | O8: =IFERROR(VLOOKUP(MATCH($B8,INDEX('Race Resuts'!$A$2:$W$23,0,MATCH(O$1,'Race Resuts'!$A$1:$W$1,0)),0),'Points Refrence'!$A$2:$B$11,2,FALSE),0) -> 18 | P8: =IFERROR(VLOOKUP(MATCH($B8,INDEX('Race Resuts'!$B$2:$W$23,0,MATCH(P$1,'Race Resuts'!$B$1:$W$1,0)),0),'Points Refrence'!$A$2:$B$11,2,FALSE),0)+IFERROR(VLOOKUP(MATCH($B8,INDEX('Sprint Race Results'!$B$2:$G$23,0,MATCH(P$1,'Sprint Race Results'!$B$1:$G$1,0)),0),'Points Refrence'!$D$2:$E$9,2,FALSE),0) -> 0 | Q8: =IFERROR(VLOOKUP(MATCH($B8,INDEX('Race Resuts'!$A$2:$W$23,0,MATCH(Q$1,'Race Resuts'!$A$1:$W$1,0)),0),'Points Refrence'!$A$2:$B$11,2,FALSE),0) -> 0 | R8: =IFERROR(VLOOKUP(MATCH($B8,INDEX('Race Resuts'!$A$2:$W$23,0,MATCH(R$1,'Race Resuts'!$A$1:$W$1,0)),0),'Points Refrence'!$A$2:$B$11,2,FALSE),0) -> 0 | S8: =IFERROR(VLOOKUP(MATCH($B8,INDEX('Race Resuts'!$A$2:$W$23,0,MATCH(S$1,'Race Resuts'!$A$1:$W$1,0)),0),'Points Refrence'!$A$2:$B$11,2,FALSE),0) -> 0 | T8: =IFERROR(VLOOKUP(MATCH($B8,INDEX('Race Resuts'!$B$2:$W$23,0,MATCH(T$1,'Race Resuts'!$B$1:$W$1,0)),0),'Points Refrence'!$A$2:$B$11,2,FALSE),0)+IFERROR(VLOOKUP(MATCH($B8,INDEX('Sprint Race Results'!$B$2:$G$23,0,MATCH(T$1,'Sprint Race Results'!$B$1:$G$1,0)),0),'Points Refrence'!$D$2:$E$9,2,FALSE),0) -> 0 | U8: =IFERROR(VLOOKUP(MATCH($B8,INDEX('Race Resuts'!$A$2:$W$23,0,MATCH(U$1,'Race Resuts'!$A$1:$W$1,0)),0),'Points Refrence'!$A$2:$B$11,2,FALSE),0) -> 0 | V8: =IFERROR(VLOOKUP(MATCH($B8,INDEX('Race Resuts'!$A$2:$W$23,0,MATCH(V$1,'Race Resuts'!$A$1:$W$1,0)),0),'Points Refrence'!$A$2:$B$11,2,FALSE),0) -> 0 | W8: =IFERROR(VLOOKUP(MATCH($B8,INDEX('Race Resuts'!$A$2:$W$23,0,MATCH(W$1,'Race Resuts'!$A$1:$W$1,0)),0),'Points Refrence'!$A$2:$B$11,2,FALSE),0) -> 0 | X8: =IFERROR(VLOOKUP(MATCH($B8,INDEX('Race Resuts'!$A$2:$W$23,0,MATCH(X$1,'Race Resuts'!$A$1:$W$1,0)),0),'Points Refrence'!$A$2:$B$11,2,FALSE),0) -> 0 | Y8: =IFERROR(VLOOKUP(MATCH($B8,INDEX('Race Resuts'!$A$2:$W$23,0,MATCH(Y$1,'Race Resuts'!$A$1:$W$1,0)),0),'Points Refrence'!$A$2:$B$11,2,FALSE),0) -> 0 | Z8: =IFERROR(VLOOKUP(MATCH($B8,INDEX('Race Resuts'!$A$2:$W$23,0,MATCH(Z$1,'Race Resuts'!$A$1:$W$1,0)),0),'Points Refrence'!$A$2:$B$11,2,FALSE),0) -> 0 | AA8: =RANK(AB8,$AB$2:$AB$23,0)+COUNTIF($AB$2:AB8,AB8)-1 -> 6 | AB8: =SUM(C8:Z8) -> 109 | AD8: =ROW()-1 -> 7 | AE8: =INDEX($B$2:$B$23,MATCH(AD8,$AA$2:$AA$23,0)) -> PIA | AF8: =INDEX($AB$2:$AB$23,MATCH(AD8,$AA$2:$AA$23,0)) -> 92
A9: Isack Hadjar | B9: HAD | C9: =IFERROR(VLOOKUP(MATCH($B9,INDEX('Race Resuts'!$A$2:$W$23,0,MATCH(C$1,'Race Resuts'!$A$1:$W$1,0)),0),'Points Refrence'!$A$2:$B$11,2,FALSE),0) -> 0 | D9: =IFERROR(_xlfn.XLOOKUP(MATCH($B9,INDEX('Race Resuts'!$B$2:$W$23,0,MATCH(D$1,'Race Resuts'!$B$1:$W$1,0)),0),'Points Refrence'!$A$2:$A$11,'Points Refrence'!$B$2:$B$11,0),0)+IFERROR(_xlfn.XLOOKUP(MATCH($B9,INDEX('Sprint Race Results'!$B$2:$G$23,0,MATCH(D$1,'Sprint Race Results'!$B$1:$G$1,0)),0),'Points Refrence'!$D$2:$D$9,'Points Refrence'!$E$2:$E$9,0),0) -> 4 | E9: =IFERROR(VLOOKUP(MATCH($B9,INDEX('Race Resuts'!$A$2:$W$23,0,MATCH(E$1,'Race Resuts'!$A$1:$W$1,0)),0),'Points Refrence'!$A$2:$B$11,2,FALSE),0) -> 0 | F9: =IFERROR(VLOOKUP(MATCH($B9,INDEX('Race Resuts'!$A$2:$W$23,0,MATCH(F$1,'Race Resuts'!$A$1:$W$1,0)),0),'Points Refrence'!$A$2:$B$11,2,FALSE),0) -> 0 | G9: =IFERROR(VLOOKUP(MATCH($B9,INDEX('Race Resuts'!$A$2:$W$23,0,MATCH(G$1,'Race Resuts'!$A$1:$W$1,0)),0),'Points Refrence'!$A$2:$B$11,2,FALSE),0) -> 0 | H9: =IFERROR(VLOOKUP(MATCH($B9,INDEX('Race Resuts'!$B$2:$W$23,0,MATCH(H$1,'Race Resuts'!$B$1:$W$1,0)),0),'Points Refrence'!$A$2:$B$11,2,FALSE),0)+IFERROR(VLOOKUP(MATCH($B9,INDEX('Sprint Race Results'!$B$2:$G$23,0,MATCH(H$1,'Sprint Race Results'!$B$1:$G$1,0)),0),'Points Refrence'!$D$2:$E$9,2,FALSE),0) -> 0 | I9: =IFERROR(VLOOKUP(MATCH($B9,INDEX('Race Resuts'!$B$2:$W$23,0,MATCH(I$1,'Race Resuts'!$B$1:$W$1,0)),0),'Points Refrence'!$A$2:$B$11,2,FALSE),0)+IFERROR(VLOOKUP(MATCH($B9,INDEX('Sprint Race Results'!$B$2:$G$23,0,MATCH(I$1,'Sprint Race Results'!$B$1:$G$1,0)),0),'Points Refrence'!$D$2:$E$9,2,FALSE),0) -> 10 | J9: =IFERROR(VLOOKUP(MATCH($B9,INDEX('Race Resuts'!$A$2:$W$23,0,MATCH(J$1,'Race Resuts'!$A$1:$W$1,0)),0),'Points Refrence'!$A$2:$B$11,2,FALSE),0) -> 12 | K9: =IFERROR(VLOOKUP(MATCH($B9,INDEX('Race Resuts'!$A$2:$W$23,0,MATCH(K$1,'Race Resuts'!$A$1:$W$1,0)),0),'Points Refrence'!$A$2:$B$11,2,FALSE),0) -> 8 | L9: =IFERROR(VLOOKUP(MATCH($B9,INDEX('Race Resuts'!$A$2:$W$23,0,MATCH(L$1,'Race Resuts'!$A$1:$W$1,0)),0),'Points Refrence'!$A$2:$B$11,2,FALSE),0) -> 8 | M9: =IFERROR(VLOOKUP(MATCH($B9,INDEX('Race Resuts'!$B$2:$W$23,0,MATCH(M$1,'Race Resuts'!$B$1:$W$1,0)),0),'Points Refrence'!$A$2:$B$11,2,FALSE),0)+IFERROR(VLOOKUP(MATCH($B9,INDEX('Sprint Race Results'!$B$2:$G$23,0,MATCH(M$1,'Sprint Race Results'!$B$1:$G$1,0)),0),'Points Refrence'!$D$2:$E$9,2,FALSE),0) -> 10 | N9: =IFERROR(VLOOKUP(MATCH($B9,INDEX('Race Resuts'!$A$2:$W$23,0,MATCH(N$1,'Race Resuts'!$A$1:$W$1,0)),0),'Points Refrence'!$A$2:$B$11,2,FALSE),0) -> 8 | O9: =IFERROR(VLOOKUP(MATCH($B9,INDEX('Race Resuts'!$A$2:$W$23,0,MATCH(O$1,'Race Resuts'!$A$1:$W$1,0)),0),'Points Refrence'!$A$2:$B$11,2,FALSE),0) -> 8 | P9: =IFERROR(VLOOKUP(MATCH($B9,INDEX('Race Resuts'!$B$2:$W$23,0,MATCH(P$1,'Race Resuts'!$B$1:$W$1,0)),0),'Points Refrence'!$A$2:$B$11,2,FALSE),0)+IFERROR(VLOOKUP(MATCH($B9,INDEX('Sprint Race Results'!$B$2:$G$23,0,MATCH(P$1,'Sprint Race Results'!$B$1:$G$1,0)),0),'Points Refrence'!$D$2:$E$9,2,FALSE),0) -> 0 | Q9: =IFERROR(VLOOKUP(MATCH($B9,INDEX('Race Resuts'!$A$2:$W$23,0,MATCH(Q$1,'Race Resuts'!$A$1:$W$1,0)),0),'Points Refrence'!$A$2:$B$11,2,FALSE),0) -> 0 | R9: =IFERROR(VLOOKUP(MATCH($B9,INDEX('Race Resuts'!$A$2:$W$23,0,MATCH(R$1,'Race Resuts'!$A$1:$W$1,0)),0),'Points Refrence'!$A$2:$B$11,2,FALSE),0) -> 0 | S9: =IFERROR(VLOOKUP(MATCH($B9,INDEX('Race Resuts'!$A$2:$W$23,0,MATCH(S$1,'Race Resuts'!$A$1:$W$1,0)),0),'Points Refrence'!$A$2:$B$11,2,FALSE),0) -> 0 | T9: =IFERROR(VLOOKUP(MATCH($B9,INDEX('Race Resuts'!$B$2:$W$23,0,MATCH(T$1,'Race Resuts'!$B$1:$W$1,0)),0),'Points Refrence'!$A$2:$B$11,2,FALSE),0)+IFERROR(VLOOKUP(MATCH($B9,INDEX('Sprint Race Results'!$B$2:$G$23,0,MATCH(T$1,'Sprint Race Results'!$B$1:$G$1,0)),0),'Points Refrence'!$D$2:$E$9,2,FALSE),0) -> 0 | U9: =IFERROR(VLOOKUP(MATCH($B9,INDEX('Race Resuts'!$A$2:$W$23,0,MATCH(U$1,'Race Resuts'!$A$1:$W$1,0)),0),'Points Refrence'!$A$2:$B$11,2,FALSE),0) -> 0 | V9: =IFERROR(VLOOKUP(MATCH($B9,INDEX('Race Resuts'!$A$2:$W$23,0,MATCH(V$1,'Race Resuts'!$A$1:$W$1,0)),0),'Points Refrence'!$A$2:$B$11,2,FALSE),0) -> 0 | W9: =IFERROR(VLOOKUP(MATCH($B9,INDEX('Race Resuts'!$A$2:$W$23,0,MATCH(W$1,'Race Resuts'!$A$1:$W$1,0)),0),'Points Refrence'!$A$2:$B$11,2,FALSE),0) -> 0 | X9: =IFERROR(VLOOKUP(MATCH($B9,INDEX('Race Resuts'!$A$2:$W$23,0,MATCH(X$1,'Race Resuts'!$A$1:$W$1,0)),0),'Points Refrence'!$A$2:$B$11,2,FALSE),0) -> 0 | Y9: =IFERROR(VLOOKUP(MATCH($B9,INDEX('Race Resuts'!$A$2:$W$23,0,MATCH(Y$1,'Race Resuts'!$A$1:$W$1,0)),0),'Points Refrence'!$A$2:$B$11,2,FALSE),0) -> 0 | Z9: =IFERROR(VLOOKUP(MATCH($B9,INDEX('Race Resuts'!$A$2:$W$23,0,MATCH(Z$1,'Race Resuts'!$A$1:$W$1,0)),0),'Points Refrence'!$A$2:$B$11,2,FALSE),0) -> 0 | AA9: =RANK(AB9,$AB$2:$AB$23,0)+COUNTIF($AB$2:AB9,AB9)-1 -> 8 | AB9: =SUM(C9:Z9) -> 68 | AD9: =ROW()-1 -> 8 | AE9: =INDEX($B$2:$B$23,MATCH(AD9,$AA$2:$AA$23,0)) -> HAD | AF9: =INDEX($AB$2:$AB$23,MATCH(AD9,$AA$2:$AA$23,0)) -> 68
A10: Pierre Gasly | B10: GAS | C10: =IFERROR(VLOOKUP(MATCH($B10,INDEX('Race Resuts'!$A$2:$W$23,0,MATCH(C$1,'Race Resuts'!$A$1:$W$1,0)),0),'Points Refrence'!$A$2:$B$11,2,FALSE),0) -> 1 | D10: =IFERROR(_xlfn.XLOOKUP(MATCH($B10,INDEX('Race Resuts'!$B$2:$W$23,0,MATCH(D$1,'Race Resuts'!$B$1:$W$1,0)),0),'Points Refrence'!$A$2:$A$11,'Points Refrence'!$B$2:$B$11,0),0)+IFERROR(_xlfn.XLOOKUP(MATCH($B10,INDEX('Sprint Race Results'!$B$2:$G$23,0,MATCH(D$1,'Sprint Race Results'!$B$1:$G$1,0)),0),'Points Refrence'!$D$2:$D$9,'Points Refrence'!$E$2:$E$9,0),0) -> 8 | E10: =IFERROR(VLOOKUP(MATCH($B10,INDEX('Race Resuts'!$A$2:$W$23,0,MATCH(E$1,'Race Resuts'!$A$1:$W$1,0)),0),'Points Refrence'!$A$2:$B$11,2,FALSE),0) -> 6 | F10: =IFERROR(VLOOKUP(MATCH($B10,INDEX('Race Resuts'!$A$2:$W$23,0,MATCH(F$1,'Race Resuts'!$A$1:$W$1,0)),0),'Points Refrence'!$A$2:$B$11,2,FALSE),0) -> 0 | G10: =IFERROR(VLOOKUP(MATCH($B10,INDEX('Race Resuts'!$A$2:$W$23,0,MATCH(G$1,'Race Resuts'!$A$1:$W$1,0)),0),'Points Refrence'!$A$2:$B$11,2,FALSE),0) -> 0 | H10: =IFERROR(VLOOKUP(MATCH($B10,INDEX('Race Resuts'!$B$2:$W$23,0,MATCH(H$1,'Race Resuts'!$B$1:$W$1,0)),0),'Points Refrence'!$A$2:$B$11,2,FALSE),0)+IFERROR(VLOOKUP(MATCH($B10,INDEX('Sprint Race Results'!$B$2:$G$23,0,MATCH(H$1,'Sprint Race Results'!$B$1:$G$1,0)),0),'Points Refrence'!$D$2:$E$9,2,FALSE),0) -> 1 | I10: =IFERROR(VLOOKUP(MATCH($B10,INDEX('Race Resuts'!$B$2:$W$23,0,MATCH(I$1,'Race Resuts'!$B$1:$W$1,0)),0),'Points Refrence'!$A$2:$B$11,2,FALSE),0)+IFERROR(VLOOKUP(MATCH($B10,INDEX('Sprint Race Results'!$B$2:$G$23,0,MATCH(I$1,'Sprint Race Results'!$B$1:$G$1,0)),0),'Points Refrence'!$D$2:$E$9,2,FALSE),0) -> 4 | J10: =IFERROR(VLOOKUP(MATCH($B10,INDEX('Race Resuts'!$A$2:$W$23,0,MATCH(J$1,'Race Resuts'!$A$1:$W$1,0)),0),'Points Refrence'!$A$2:$B$11,2,FALSE),0) -> 15 | K10: =IFERROR(VLOOKUP(MATCH($B10,INDEX('Race Resuts'!$A$2:$W$23,0,MATCH(K$1,'Race Resuts'!$A$1:$W$1,0)),0),'Points Refrence'!$A$2:$B$11,2,FALSE),0) -> 6 | L10: =IFERROR(VLOOKUP(MATCH($B10,INDEX('Race Resuts'!$A$2:$W$23,0,MATCH(L$1,'Race Resuts'!$A$1:$W$1,0)),0),'Points Refrence'!$A$2:$B$11,2,FALSE),0) -> 0 | M10: =IFERROR(VLOOKUP(MATCH($B10,INDEX('Race Resuts'!$B$2:$W$23,0,MATCH(M$1,'Race Resuts'!$B$1:$W$1,0)),0),'Points Refrence'!$A$2:$B$11,2,FALSE),0)+IFERROR(VLOOKUP(MATCH($B10,INDEX('Sprint Race Results'!$B$2:$G$23,0,MATCH(M$1,'Sprint Race Results'!$B$1:$G$1,0)),0),'Points Refrence'!$D$2:$E$9,2,FALSE),0) -> 1 | N10: =IFERROR(VLOOKUP(MATCH($B10,INDEX('Race Resuts'!$A$2:$W$23,0,MATCH(N$1,'Race Resuts'!$A$1:$W$1,0)),0),'Points Refrence'!$A$2:$B$11,2,FALSE),0) -> 0 | O10: =IFERROR(VLOOKUP(MATCH($B10,INDEX('Race Resuts'!$A$2:$W$23,0,MATCH(O$1,'Race Resuts'!$A$1:$W$1,0)),0),'Points Refrence'!$A$2:$B$11,2,FALSE),0) -> 0 | P10: =IFERROR(VLOOKUP(MATCH($B10,INDEX('Race Resuts'!$B$2:$W$23,0,MATCH(P$1,'Race Resuts'!$B$1:$W$1,0)),0),'Points Refrence'!$A$2:$B$11,2,FALSE),0)+IFERROR(VLOOKUP(MATCH($B10,INDEX('Sprint Race Results'!$B$2:$G$23,0,MATCH(P$1,'Sprint Race Results'!$B$1:$G$1,0)),0),'Points Refrence'!$D$2:$E$9,2,FALSE),0) -> 0 | Q10: =IFERROR(VLOOKUP(MATCH($B10,INDEX('Race Resuts'!$A$2:$W$23,0,MATCH(Q$1,'Race Resuts'!$A$1:$W$1,0)),0),'Points Refrence'!$A$2:$B$11,2,FALSE),0) -> 0 | R10: =IFERROR(VLOOKUP(MATCH($B10,INDEX('Race Resuts'!$A$2:$W$23,0,MATCH(R$1,'Race Resuts'!$A$1:$W$1,0)),0),'Points Refrence'!$A$2:$B$11,2,FALSE),0) -> 0 | S10: =IFERROR(VLOOKUP(MATCH($B10,INDEX('Race Resuts'!$A$2:$W$23,0,MATCH(S$1,'Race Resuts'!$A$1:$W$1,0)),0),'Points Refrence'!$A$2:$B$11,2,FALSE),0) -> 0 | T10: =IFERROR(VLOOKUP(MATCH($B10,INDEX('Race Resuts'!$B$2:$W$23,0,MATCH(T$1,'Race Resuts'!$B$1:$W$1,0)),0),'Points Refrence'!$A$2:$B$11,2,FALSE),0)+IFERROR(VLOOKUP(MATCH($B10,INDEX('Sprint Race Results'!$B$2:$G$23,0,MATCH(T$1,'Sprint Race Results'!$B$1:$G$1,0)),0),'Points Refrence'!$D$2:$E$9,2,FALSE),0) -> 0 | U10: =IFERROR(VLOOKUP(MATCH($B10,INDEX('Race Resuts'!$A$2:$W$23,0,MATCH(U$1,'Race Resuts'!$A$1:$W$1,0)),0),'Points Refrence'!$A$2:$B$11,2,FALSE),0) -> 0 | V10: =IFERROR(VLOOKUP(MATCH($B10,INDEX('Race Resuts'!$A$2:$W$23,0,MATCH(V$1,'Race Resuts'!$A$1:$W$1,0)),0),'Points Refrence'!$A$2:$B$11,2,FALSE),0) -> 0 | W10: =IFERROR(VLOOKUP(MATCH($B10,INDEX('Race Resuts'!$A$2:$W$23,0,MATCH(W$1,'Race Resuts'!$A$1:$W$1,0)),0),'Points Refrence'!$A$2:$B$11,2,FALSE),0) -> 0 | X10: =IFERROR(VLOOKUP(MATCH($B10,INDEX('Race Resuts'!$A$2:$W$23,0,MATCH(X$1,'Race Resuts'!$A$1:$W$1,0)),0),'Points Refrence'!$A$2:$B$11,2,FALSE),0) -> 0 | Y10: =IFERROR(VLOOKUP(MATCH($B10,INDEX('Race Resuts'!$A$2:$W$23,0,MATCH(Y$1,'Race Resuts'!$A$1:$W$1,0)),0),'Points Refrence'!$A$2:$B$11,2,FALSE),0) -> 0 | Z10: =IFERROR(VLOOKUP(MATCH($B10,INDEX('Race Resuts'!$A$2:$W$23,0,MATCH(Z$1,'Race Resuts'!$A$1:$W$1,0)),0),'Points Refrence'!$A$2:$B$11,2,FALSE),0) -> 0 | AA10: =RANK(AB10,$AB$2:$AB$23,0)+COUNTIF($AB$2:AB10,AB10)-1 -> 10 | AB10: =SUM(C10:Z10) -> 42 | AD10: =ROW()-1 -> 9 | AE10: =INDEX($B$2:$B$23,MATCH(AD10,$AA$2:$AA$23,0)) -> LAW | AF10: =INDEX($AB$2:$AB$23,MATCH(AD10,$AA$2:$AA$23,0)) -> 43
A11: Franco Colapinto | B11: COL | C11: =IFERROR(VLOOKUP(MATCH($B11,INDEX('Race Resuts'!$A$2:$W$23,0,MATCH(C$1,'Race Resuts'!$A$1:$W$1,0)),0),'Points Refrence'!$A$2:$B$11,2,FALSE),0) -> 0 | D11: =IFERROR(_xlfn.XLOOKUP(MATCH($B11,INDEX('Race Resuts'!$B$2:$W$23,0,MATCH(D$1,'Race Resuts'!$B$1:$W$1,0)),0),'Points Refrence'!$A$2:$A$11,'Points Refrence'!$B$2:$B$11,0),0)+IFERROR(_xlfn.XLOOKUP(MATCH($B11,INDEX('Sprint Race Results'!$B$2:$G$23,0,MATCH(D$1,'Sprint Race Results'!$B$1:$G$1,0)),0),'Points Refrence'!$D$2:$D$9,'Points Refrence'!$E$2:$E$9,0),0) -> 1 | E11: =IFERROR(VLOOKUP(MATCH($B11,INDEX('Race Resuts'!$A$2:$W$23,0,MATCH(E$1,'Race Resuts'!$A$1:$W$1,0)),0),'Points Refrence'!$A$2:$B$11,2,FALSE),0) -> 0 | F11: =IFERROR(VLOOKUP(MATCH($B11,INDEX('Race Resuts'!$A$2:$W$23,0,MATCH(F$1,'Race Resuts'!$A$1:$W$1,0)),0),'Points Refrence'!$A$2:$B$11,2,FALSE),0) -> 0 | G11: =IFERROR(VLOOKUP(MATCH($B11,INDEX('Race Resuts'!$A$2:$W$23,0,MATCH(G$1,'Race Resuts'!$A$1:$W$1,0)),0),'Points Refrence'!$A$2:$B$11,2,FALSE),0) -> 0 | H11: =IFERROR(VLOOKUP(MATCH($B11,INDEX('Race Resuts'!$B$2:$W$23,0,MATCH(H$1,'Race Resuts'!$B$1:$W$1,0)),0),'Points Refrence'!$A$2:$B$11,2,FALSE),0)+IFERROR(VLOOKUP(MATCH($B11,INDEX('Sprint Race Results'!$B$2:$G$23,0,MATCH(H$1,'Sprint Race Results'!$B$1:$G$1,0)),0),'Points Refrence'!$D$2:$E$9,2,FALSE),0) -> 6 | I11: =IFERROR(VLOOKUP(MATCH($B11,INDEX('Race Resuts'!$B$2:$W$23,0,MATCH(I$1,'Race Resuts'!$B$1:$W$1,0)),0),'Points Refrence'!$A$2:$B$11,2,FALSE),0)+IFERROR(VLOOKUP(MATCH($B11,INDEX('Sprint Race Results'!$B$2:$G$23,0,MATCH(I$1,'Sprint Race Results'!$B$1:$G$1,0)),0),'Points Refrence'!$D$2:$E$9,2,FALSE),0) -> 8 | J11: =IFERROR(VLOOKUP(MATCH($B11,INDEX('Race Resuts'!$A$2:$W$23,0,MATCH(J$1,'Race Resuts'!$A$1:$W$1,0)),0),'Points Refrence'!$A$2:$B$11,2,FALSE),0) -> 0 | K11: =IFERROR(VLOOKUP(MATCH($B11,INDEX('Race Resuts'!$A$2:$W$23,0,MATCH(K$1,'Race Resuts'!$A$1:$W$1,0)),0),'Points Refrence'!$A$2:$B$11,2,FALSE),0) -> 1 | L11: =IFERROR(VLOOKUP(MATCH($B11,INDEX('Race Resuts'!$A$2:$W$23,0,MATCH(L$1,'Race Resuts'!$A$1:$W$1,0)),0),'Points Refrence'!$A$2:$B$11,2,FALSE),0) -> 0 | M11: =IFERROR(VLOOKUP(MATCH($B11,INDEX('Race Resuts'!$B$2:$W$23,0,MATCH(M$1,'Race Resuts'!$B$1:$W$1,0)),0),'Points Refrence'!$A$2:$B$11,2,FALSE),0)+IFERROR(VLOOKUP(MATCH($B11,INDEX('Sprint Race Results'!$B$2:$G$23,0,MATCH(M$1,'Sprint Race Results'!$B$1:$G$1,0)),0),'Points Refrence'!$D$2:$E$9,2,FALSE),0) -> 2 | N11: =IFERROR(VLOOKUP(MATCH($B11,INDEX('Race Resuts'!$A$2:$W$23,0,MATCH(N$1,'Race Resuts'!$A$1:$W$1,0)),0),'Points Refrence'!$A$2:$B$11,2,FALSE),0) -> 1 | O11: =IFERROR(VLOOKUP(MATCH($B11,INDEX('Race Resuts'!$A$2:$W$23,0,MATCH(O$1,'Race Resuts'!$A$1:$W$1,0)),0),'Points Refrence'!$A$2:$B$11,2,FALSE),0) -> 0 | P11: =IFERROR(VLOOKUP(MATCH($B11,INDEX('Race Resuts'!$B$2:$W$23,0,MATCH(P$1,'Race Resuts'!$B$1:$W$1,0)),0),'Points Refrence'!$A$2:$B$11,2,FALSE),0)+IFERROR(VLOOKUP(MATCH($B11,INDEX('Sprint Race Results'!$B$2:$G$23,0,MATCH(P$1,'Sprint Race Results'!$B$1:$G$1,0)),0),'Points Refrence'!$D$2:$E$9,2,FALSE),0) -> 0 | Q11: =IFERROR(VLOOKUP(MATCH($B11,INDEX('Race Resuts'!$A$2:$W$23,0,MATCH(Q$1,'Race Resuts'!$A$1:$W$1,0)),0),'Points Refrence'!$A$2:$B$11,2,FALSE),0) -> 0 | R11: =IFERROR(VLOOKUP(MATCH($B11,INDEX('Race Resuts'!$A$2:$W$23,0,MATCH(R$1,'Race Resuts'!$A$1:$W$1,0)),0),'Points Refrence'!$A$2:$B$11,2,FALSE),0) -> 0 | S11: =IFERROR(VLOOKUP(MATCH($B11,INDEX('Race Resuts'!$A$2:$W$23,0,MATCH(S$1,'Race Resuts'!$A$1:$W$1,0)),0),'Points Refrence'!$A$2:$B$11,2,FALSE),0) -> 0 | T11: =IFERROR(VLOOKUP(MATCH($B11,INDEX('Race Resuts'!$B$2:$W$23,0,MATCH(T$1,'Race Resuts'!$B$1:$W$1,0)),0),'Points Refrence'!$A$2:$B$11,2,FALSE),0)+IFERROR(VLOOKUP(MATCH($B11,INDEX('Sprint Race Results'!$B$2:$G$23,0,MATCH(T$1,'Sprint Race Results'!$B$1:$G$1,0)),0),'Points Refrence'!$D$2:$E$9,2,FALSE),0) -> 0 | U11: =IFERROR(VLOOKUP(MATCH($B11,INDEX('Race Resuts'!$A$2:$W$23,0,MATCH(U$1,'Race Resuts'!$A$1:$W$1,0)),0),'Points Refrence'!$A$2:$B$11,2,FALSE),0) -> 0 | V11: =IFERROR(VLOOKUP(MATCH($B11,INDEX('Race Resuts'!$A$2:$W$23,0,MATCH(V$1,'Race Resuts'!$A$1:$W$1,0)),0),'Points Refrence'!$A$2:$B$11,2,FALSE),0) -> 0 | W11: =IFERROR(VLOOKUP(MATCH($B11,INDEX('Race Resuts'!$A$2:$W$23,0,MATCH(W$1,'Race Resuts'!$A$1:$W$1,0)),0),'Points Refrence'!$A$2:$B$11,2,FALSE),0) -> 0 | X11: =IFERROR(VLOOKUP(MATCH($B11,INDEX('Race Resuts'!$A$2:$W$23,0,MATCH(X$1,'Race Resuts'!$A$1:$W$1,0)),0),'Points Refrence'!$A$2:$B$11,2,FALSE),0) -> 0 | Y11: =IFERROR(VLOOKUP(MATCH($B11,INDEX('Race Resuts'!$A$2:$W$23,0,MATCH(Y$1,'Race Resuts'!$A$1:$W$1,0)),0),'Points Refrence'!$A$2:$B$11,2,FALSE),0) -> 0 | Z11: =IFERROR(VLOOKUP(MATCH($B11,INDEX('Race Resuts'!$A$2:$W$23,0,MATCH(Z$1,'Race Resuts'!$A$1:$W$1,0)),0),'Points Refrence'!$A$2:$B$11,2,FALSE),0) -> 0 | AA11: =RANK(AB11,$AB$2:$AB$23,0)+COUNTIF($AB$2:AB11,AB11)-1 -> 12 | AB11: =SUM(C11:Z11) -> 19 | AD11: =ROW()-1 -> 10 | AE11: =INDEX($B$2:$B$23,MATCH(AD11,$AA$2:$AA$23,0)) -> GAS | AF11: =INDEX($AB$2:$AB$23,MATCH(AD11,$AA$2:$AA$23,0)) -> 42
A12: Arvid Lindblad | B12: LIN | C12: =IFERROR(VLOOKUP(MATCH($B12,INDEX('Race Resuts'!$A$2:$W$23,0,MATCH(C$1,'Race Resuts'!$A$1:$W$1,0)),0),'Points Refrence'!$A$2:$B$11,2,FALSE),0) -> 4 | D12: =IFERROR(_xlfn.XLOOKUP(MATCH($B12,INDEX('Race Resuts'!$B$2:$W$23,0,MATCH(D$1,'Race Resuts'!$B$1:$W$1,0)),0),'Points Refrence'!$A$2:$A$11,'Points Refrence'!$B$2:$B$11,0),0)+IFERROR(_xlfn.XLOOKUP(MATCH($B12,INDEX('Sprint Race Results'!$B$2:$G$23,0,MATCH(D$1,'Sprint Race Results'!$B$1:$G$1,0)),0),'Points Refrence'!$D$2:$D$9,'Points Refrence'!$E$2:$E$9,0),0) -> 0 | E12: =IFERROR(VLOOKUP(MATCH($B12,INDEX('Race Resuts'!$A$2:$W$23,0,MATCH(E$1,'Race Resuts'!$A$1:$W$1,0)),0),'Points Refrence'!$A$2:$B$11,2,FALSE),0) -> 0 | F12: =IFERROR(VLOOKUP(MATCH($B12,INDEX('Race Resuts'!$A$2:$W$23,0,MATCH(F$1,'Race Resuts'!$A$1:$W$1,0)),0),'Points Refrence'!$A$2:$B$11,2,FALSE),0) -> 0 | G12: =IFERROR(VLOOKUP(MATCH($B12,INDEX('Race Resuts'!$A$2:$W$23,0,MATCH(G$1,'Race Resuts'!$A$1:$W$1,0)),0),'Points Refrence'!$A$2:$B$11,2,FALSE),0) -> 0 | H12: =IFERROR(VLOOKUP(MATCH($B12,INDEX('Race Resuts'!$B$2:$W$23,0,MATCH(H$1,'Race Resuts'!$B$1:$W$1,0)),0),'Points Refrence'!$A$2:$B$11,2,FALSE),0)+IFERROR(VLOOKUP(MATCH($B12,INDEX('Sprint Race Results'!$B$2:$G$23,0,MATCH(H$1,'Sprint Race Results'!$B$1:$G$1,0)),0),'Points Refrence'!$D$2:$E$9,2,FALSE),0) -> 0 | I12: =IFERROR(VLOOKUP(MATCH($B12,INDEX('Race Resuts'!$B$2:$W$23,0,MATCH(I$1,'Race Resuts'!$B$1:$W$1,0)),0),'Points Refrence'!$A$2:$B$11,2,FALSE),0)+IFERROR(VLOOKUP(MATCH($B12,INDEX('Sprint Race Results'!$B$2:$G$23,0,MATCH(I$1,'Sprint Race Results'!$B$1:$G$1,0)),0),'Points Refrence'!$D$2:$E$9,2,FALSE),0) -> 1 | J12: =IFERROR(VLOOKUP(MATCH($B12,INDEX('Race Resuts'!$A$2:$W$23,0,MATCH(J$1,'Race Resuts'!$A$1:$W$1,0)),0),'Points Refrence'!$A$2:$B$11,2,FALSE),0) -> 6 | K12: =IFERROR(VLOOKUP(MATCH($B12,INDEX('Race Resuts'!$A$2:$W$23,0,MATCH(K$1,'Race Resuts'!$A$1:$W$1,0)),0),'Points Refrence'!$A$2:$B$11,2,FALSE),0) -> 2 | L12: =IFERROR(VLOOKUP(MATCH($B12,INDEX('Race Resuts'!$A$2:$W$23,0,MATCH(L$1,'Race Resuts'!$A$1:$W$1,0)),0),'Points Refrence'!$A$2:$B$11,2,FALSE),0) -> 1 | M12: =IFERROR(VLOOKUP(MATCH($B12,INDEX('Race Resuts'!$B$2:$W$23,0,MATCH(M$1,'Race Resuts'!$B$1:$W$1,0)),0),'Points Refrence'!$A$2:$B$11,2,FALSE),0)+IFERROR(VLOOKUP(MATCH($B12,INDEX('Sprint Race Results'!$B$2:$G$23,0,MATCH(M$1,'Sprint Race Results'!$B$1:$G$1,0)),0),'Points Refrence'!$D$2:$E$9,2,FALSE),0) -> 6 | N12: =IFERROR(VLOOKUP(MATCH($B12,INDEX('Race Resuts'!$A$2:$W$23,0,MATCH(N$1,'Race Resuts'!$A$1:$W$1,0)),0),'Points Refrence'!$A$2:$B$11,2,FALSE),0) -> 2 | O12: =IFERROR(VLOOKUP(MATCH($B12,INDEX('Race Resuts'!$A$2:$W$23,0,MATCH(O$1,'Race Resuts'!$A$1:$W$1,0)),0),'Points Refrence'!$A$2:$B$11,2,FALSE),0) -> 1 | P12: =IFERROR(VLOOKUP(MATCH($B12,INDEX('Race Resuts'!$B$2:$W$23,0,MATCH(P$1,'Race Resuts'!$B$1:$W$1,0)),0),'Points Refrence'!$A$2:$B$11,2,FALSE),0)+IFERROR(VLOOKUP(MATCH($B12,INDEX('Sprint Race Results'!$B$2:$G$23,0,MATCH(P$1,'Sprint Race Results'!$B$1:$G$1,0)),0),'Points Refrence'!$D$2:$E$9,2,FALSE),0) -> 0 | Q12: =IFERROR(VLOOKUP(MATCH($B12,INDEX('Race Resuts'!$A$2:$W$23,0,MATCH(Q$1,'Race Resuts'!$A$1:$W$1,0)),0),'Points Refrence'!$A$2:$B$11,2,FALSE),0) -> 0 | R12: =IFERROR(VLOOKUP(MATCH($B12,INDEX('Race Resuts'!$A$2:$W$23,0,MATCH(R$1,'Race Resuts'!$A$1:$W$1,0)),0),'Points Refrence'!$A$2:$B$11,2,FALSE),0) -> 0 | S12: =IFERROR(VLOOKUP(MATCH($B12,INDEX('Race Resuts'!$A$2:$W$23,0,MATCH(S$1,'Race Resuts'!$A$1:$W$1,0)),0),'Points Refrence'!$A$2:$B$11,2,FALSE),0) -> 0 | T12: =IFERROR(VLOOKUP(MATCH($B12,INDEX('Race Resuts'!$B$2:$W$23,0,MATCH(T$1,'Race Resuts'!$B$1:$W$1,0)),0),'Points Refrence'!$A$2:$B$11,2,FALSE),0)+IFERROR(VLOOKUP(MATCH($B12,INDEX('Sprint Race Results'!$B$2:$G$23,0,MATCH(T$1,'Sprint Race Results'!$B$1:$G$1,0)),0),'Points Refrence'!$D$2:$E$9,2,FALSE),0) -> 0 | U12: =IFERROR(VLOOKUP(MATCH($B12,INDEX('Race Resuts'!$A$2:$W$23,0,MATCH(U$1,'Race Resuts'!$A$1:$W$1,0)),0),'Points Refrence'!$A$2:$B$11,2,FALSE),0) -> 0 | V12: =IFERROR(VLOOKUP(MATCH($B12,INDEX('Race Resuts'!$A$2:$W$23,0,MATCH(V$1,'Race Resuts'!$A$1:$W$1,0)),0),'Points Refrence'!$A$2:$B$11,2,FALSE),0) -> 0 | W12: =IFERROR(VLOOKUP(MATCH($B12,INDEX('Race Resuts'!$A$2:$W$23,0,MATCH(W$1,'Race Resuts'!$A$1:$W$1,0)),0),'Points Refrence'!$A$2:$B$11,2,FALSE),0) -> 0 | X12: =IFERROR(VLOOKUP(MATCH($B12,INDEX('Race Resuts'!$A$2:$W$23,0,MATCH(X$1,'Race Resuts'!$A$1:$W$1,0)),0),'Points Refrence'!$A$2:$B$11,2,FALSE),0) -> 0 | Y12: =IFERROR(VLOOKUP(MATCH($B12,INDEX('Race Resuts'!$A$2:$W$23,0,MATCH(Y$1,'Race Resuts'!$A$1:$W$1,0)),0),'Points Refrence'!$A$2:$B$11,2,FALSE),0) -> 0 | Z12: =IFERROR(VLOOKUP(MATCH($B12,INDEX('Race Resuts'!$A$2:$W$23,0,MATCH(Z$1,'Race Resuts'!$A$1:$W$1,0)),0),'Points Refrence'!$A$2:$B$11,2,FALSE),0) -> 0 | AA12: =RANK(AB12,$AB$2:$AB$23,0)+COUNTIF($AB$2:AB12,AB12)-1 -> 11 | AB12: =SUM(C12:Z12) -> 23 | AD12: =ROW()-1 -> 11 | AE12: =INDEX($B$2:$B$23,MATCH(AD12,$AA$2:$AA$23,0)) -> LIN | AF12: =INDEX($AB$2:$AB$23,MATCH(AD12,$AA$2:$AA$23,0)) -> 23
